Workbook

Sheet predicciones_pcsaft
A1: Target mass (g): | B1: 7 | C1: ← change here to rescale all masses
A2: Aroma: 2-phenylethanol
A3: Yellow = paste z (mass fracs) from software | Green = auto-calculated masses
A5: Solvent | B5: TL# | C5: z_aroma | D5: z_solvent | E5: z_water | F5: Σz (check) | G5: m_aroma (g) | H5: m_solvent (g) | I5: m_water (g) | J5: m_total (g)
A6: 2m3b2oh | B6: 1 | F6: =IF(C6="","",C6+D6+E6) | G6: =IF(C6="","",C6*$B$1) | H6: =IF(D6="","",D6*$B$1) | I6: =IF(E6="","",E6*$B$1) | J6: =IF(G6="","",G6+H6+I6)
B7: 2 | F7: =IF(C7="","",C7+D7+E7) | G7: =IF(C7="","",C7*$B$1) | H7: =IF(D7="","",D7*$B$1) | I7: =IF(E7="","",E7*$B$1) | J7: =IF(G7="","",G7+H7+I7)
B8: 3 | F8: =IF(C8="","",C8+D8+E8) | G8: =IF(C8="","",C8*$B$1) | H8: =IF(D8="","",D8*$B$1) | I8: =IF(E8="","",E8*$B$1) | J8: =IF(G8="","",G8+H8+I8)
B9: 4 | F9: =IF(C9="","",C9+D9+E9) | G9: =IF(C9="","",C9*$B$1) | H9: =IF(D9="","",D9*$B$1) | I9: =IF(E9="","",E9*$B$1) | J9: =IF(G9="","",G9+H9+I9)
B10: 5 | F10: =IF(C10="","",C10+D10+E10) | G10: =IF(C10="","",C10*$B$1) | H10: =IF(D10="","",D10*$B$1) | I10: =IF(E10="","",E10*$B$1) | J10: =IF(G10="","",G10+H10+I10)
A12: 2m2boh | B12: 1 | F12: =IF(C12="","",C12+D12+E12) | G12: =IF(C12="","",C12*$B$1) | H12: =IF(D12="","",D12*$B$1) | I12: =IF(E12="","",E12*$B$1) | J12: =IF(G12="","",G12+H12+I12)
B13: 2 | F13: =IF(C13="","",C13+D13+E13) | G13: =IF(C13="","",C13*$B$1) | H13: =IF(D13="","",D13*$B$1) | I13: =IF(E13="","",E13*$B$1) | J13: =IF(G13="","",G13+H13+I13)
B14: 3 | F14: =IF(C14="","",C14+D14+E14) | G14: =IF(C14="","",C14*$B$1) | H14: =IF(D14="","",D14*$B$1) | I14: =IF(E14="","",E14*$B$1) | J14: =IF(G14="","",G14+H14+I14)
B15: 4 | F15: =IF(C15="","",C15+D15+E15) | G15: =IF(C15="","",C15*$B$1) | H15: =IF(D15="","",D15*$B$1) | I15: =IF(E15="","",E15*$B$1) | J15: =IF(G15="","",G15+H15+I15)
B16: 5 | F16: =IF(C16="","",C16+D16+E16) | G16: =IF(C16="","",C16*$B$1) | H16: =IF(D16="","",D16*$B$1) | I16: =IF(E16="","",E16*$B$1) | J16: =IF(G16="","",G16+H16+I16)
A18: hexoh | B18: 1 | F18: =IF(C18="","",C18+D18+E18) | G18: =IF(C18="","",C18*$B$1) | H18: =IF(D18="","",D18*$B$1) | I18: =IF(E18="","",E18*$B$1) | J18: =IF(G18="","",G18+H18+I18)
B19: 2 | F19: =IF(C19="","",C19+D19+E19) | G19: =IF(C19="","",C19*$B$1) | H19: =IF(D19="","",D19*$B$1) | I19: =IF(E19="","",E19*$B$1) | J19: =IF(G19="","",G19+H19+I19)
B20: 3 | F20: =IF(C20="","",C20+D20+E20) | G20: =IF(C20="","",C20*$B$1) | H20: =IF(D20="","",D20*$B$1) | I20: =IF(E20="","",E20*$B$1) | J20: =IF(G20="","",G20+H20+I20)
B21: 4 | F21: =IF(C21="","",C21+D21+E21) | G21: =IF(C21="","",C21*$B$1) | H21: =IF(D21="","",D21*$B$1) | I21: =IF(E21="","",E21*$B$1) | J21: =IF(G21="","",G21+H21+I21)
B22: 5 | F22: =IF(C22="","",C22+D22+E22) | G22: =IF(C22="","",C22*$B$1) | H22: =IF(D22="","",D22*$B$1) | I22: =IF(E22="","",E22*$B$1) | J22: =IF(G22="","",G22+H22+I22)
A24: octoh | B24: 1 | F24: =IF(C24="","",C24+D24+E24) | G24: =IF(C24="","",C24*$B$1) | H24: =IF(D24="","",D24*$B$1) | I24: =IF(E24="","",E24*$B$1) | J24: =IF(G24="","",G24+H24+I24)
B25: 2 | F25: =IF(C25="","",C25+D25+E25) | G25: =IF(C25="","",C25*$B$1) | H25: =IF(D25="","",D25*$B$1) | I25: =IF(E25="","",E25*$B$1) | J25: =IF(G25="","",G25+H25+I25)
B26: 3 | F26: =IF(C26="","",C26+D26+E26) | G26: =IF(C26="","",C26*$B$1) | H26: =IF(D26="","",D26*$B$1) | I26: =IF(E26="","",E26*$B$1) | J26: =IF(G26="","",G26+H26+I26)
B27: 4 | F27: =IF(C27="","",C27+D27+E27) | G27: =IF(C27="","",C27*$B$1) | H27: =IF(D27="","",D27*$B$1) | I27: =IF(E27="","",E27*$B$1) | J27: =IF(G27="","",G27+H27+I27)
B28: 5 | F28: =IF(C28="","",C28+D28+E28) | G28: =IF(C28="","",C28*$B$1) | H28: =IF(D28="","",D28*$B$1) | I28: =IF(E28="","",E28*$B$1) | J28: =IF(G28="","",G28+H28+I28)
A30: mibk | B30: 1 | F30: =IF(C30="","",C30+D30+E30) | G30: =IF(C30="","",C30*$B$1) | H30: =IF(D30="","",D30*$B$1) | I30: =IF(E30="","",E30*$B$1) | J30: =IF(G30="","",G30+H30+I30)
B31: 2 | F31: =IF(C31="","",C31+D31+E31) | G31: =IF(C31="","",C31*$B$1) | H31: =IF(D31="","",D31*$B$1) | I31: =IF(E31="","",E31*$B$1) | J31: =IF(G31="","",G31+H31+I31)
B32: 3 | F32: =IF(C32="","",C32+D32+E32) | G32: =IF(C32="","",C32*$B$1) | H32: =IF(D32="","",D32*$B$1) | I32: =IF(E32="","",E32*$B$1) | J32: =IF(G32="","",G32+H32+I32)
B33: 4 | F33: =IF(C33="","",C33+D33+E33) | G33: =IF(C33="","",C33*$B$1) | H33: =IF(D33="","",D33*$B$1) | I33: =IF(E33="","",E33*$B$1) | J33: =IF(G33="","",G33+H33+I33)
B34: 5 | F34: =IF(C34="","",C34+D34+E34) | G34: =IF(C34="","",C34*$B$1) | H34: =IF(D34="","",D34*$B$1) | I34: =IF(E34="","",E34*$B$1) | J34: =IF(G34="","",G34+H34+I34)
A36: 2octanone | B36: 1 | F36: =IF(C36="","",C36+D36+E36) | G36: =IF(C36="","",C36*$B$1) | H36: =IF(D36="","",D36*$B$1) | I36: =IF(E36="","",E36*$B$1) | J36: =IF(G36="","",G36+H36+I36)
B37: 2 | F37: =IF(C37="","",C37+D37+E37) | G37: =IF(C37="","",C37*$B$1) | H37: =IF(D37="","",D37*$B$1) | I37: =IF(E37="","",E37*$B$1) | J37: =IF(G37="","",G37+H37+I37)
B38: 3 | F38: =IF(C38="","",C38+D38+E38) | G38: =IF(C38="","",C38*$B$1) | H38: =IF(D38="","",D38*$B$1) | I38: =IF(E38="","",E38*$B$1) | J38: =IF(G38="","",G38+H38+I38)
B39: 4 | F39: =IF(C39="","",C39+D39+E39) | G39: =IF(C39="","",C39*$B$1) | H39: =IF(D39="","",D39*$B$1) | I39: =IF(E39="","",E39*$B$1) | J39: =IF(G39="","",G39+H39+I39)
B40: 5 | F40: =IF(C40="","",C40+D40+E40) | G40: =IF(C40="","",C40*$B$1) | H40: =IF(D40="","",D40*$B$1) | I40: =IF(E40="","",E40*$B$1) | J40: =IF(G40="","",G40+H40+I40)

Sheet Dashboard
A1: LLE Experiments Dashboard
A4: DES Systems
A5: Aroma | B5: Solvents | C5: Tie Lines | D5: Status
A7: 2-phenylethanol | B7: 9 DES | C7: 45 | D7: TODO: Ratio
A11: Data Sources:
A12: • Componentes: Densities (col P), MW (col M), Purity (col I)

Sheet Componentes
A1: IDENTIFICADOR | G1: INVENTARIO | M1: PROPIEDADES | S1: SEGURIDAD | V1: METADATA
A2: ID | B2: Chemical Name | C2: Common Name(s) | D2: CAS Number | E2: Formula | F2: Canonical SMILES | G2: Location | H2: Supplier | I2: Grade/Purity | J2: Lot Number | K2: Quantity | L2: Unit | M2: MW | N2: Tb | O2: Tm | P2: ρ (25°C) | Q2: η (25°C) | R2: Pᵛᵃᵖ (25°C) | S2: Flash Point | T2: Hazard Class | U2: Storage | V2: Date Received | W2: Status | X2: Notes | AA2: comp_id | AB2: MW | AC2: purity
A3: Internal component code | B3: IUPAC or standard name | C3: Alternative names | D3: CAS registry number | E3: Molecular formula | F3: For modeling/databases | G3: Lab position (e.g., 3.1) | H3: Vendor name | I3: (Según batch) | J3: Batch identifier | K3: Amount available | L3: mL, g, kg, etc. | M3: g/mol | N3: °C (1 atm) | O3: °C | P3: g/cm³ | Q3: mPa·s | R3: kPa | S3: °C | T3: GHS classification | U3: Requirements | V3: YYYY-MM-DD | W3: Active/Depleted | X3: Additional info | AA3: beta | AB3: 192.3 | AC3: 0.978
A4: beta | B4: b-ionone (trans) | C4: - | D4: 14901-07-6 | E4: C13H20O | F4: CC1=C(C(CCC1)(C)C)/C=C/C(=O)C | G4: REFRIGERADOR | H4: Sigma-Aldrich | I4: 97.8% (GC) | J4: SHBL2869 | K4: 1 | L4: L | M4: 192.3 | N4: 266 | O4: - | P4: 0.94498 | R4: - | S4: - | T4: - | U4: - | V4: - | W4: Active | AA4: 2pe | AB4: 122.16 | AC4: 1
A5: 2pe | B5: 2-phenylethanol | C5: - | D5: 60-12-8 | E5: C8H10O | F5: OCCc1ccccc1 | G5: 3.x | H5: Sigma-Aldrich | I5: > 99.9% (GC) | J5: SDBB2371 | K5: 1 | L5: L | M5: 122.16 | N5: 219 | O5: - | P5: 1.01985 | R5: - | S5: - | T5: - | U5: - | V5: - | W5: Active | AA5: gamma | AB5: 170.25 | AC5: 0.987
A6: gamma | B6: g-decalactone | C6: - | D6: 706-14-9 | E6: C10H18O2 | F6: CCCCCCC1CCC(=O)O1 | G6: 3.x | H6: Sigma-Aldrich | I6: 98.7% (GC) | J6: SHBR4960 | K6: 1 | L6: L | M6: 170.25 | N6: 285 | O6: - | P6: 0.95292 | R6: - | S6: - | T6: - | U6: - | V6: - | W6: Active | AA6: 2m3b2oh | AB6: 86.13 | AC6: 0.996
A7: 2m3b2oh | B7: 2-methyl-3-buten-2-ol | C7: 2M3B2OH | D7: 115-18-4 | E7: C5H10O | F7: CC(C)(C=C)O | G7: REFRIGERADOR | H7: Aldrich | I7: 99.6% (GC) | J7: STBH5331 | K7: 1 | L7: L | M7: 86.13 | N7: 99 | O7: - | P7: 0.82388 | R7: - | S7: - | T7: - | U7: - | V7: - | W7: Active | AA7: 2m2boh | AB7: 88.15 | AC7: 1
A8: 2m2boh | B8: 2-methyl-2-butanol | C8: tert-amyl alcohol | D8: 75-85-4 | E8: C5H12O | F8: CCC(C)(C)O | G8: 3.2 | H8: Sigma-Aldrich | I8: >99.9% (GC) | J8: SDBB4598 | K8: 1 | L8: L | M8: 88.15 | N8: 102 | O8: - | P8: 0.80899 | R8: - | S8: - | T8: - | U8: - | V8: - | W8: Active | AA8: hexoh | AB8: 102.17 | AC8: 0.998
A9: hexoh | B9: 1-hexanol | C9: - | D9: 111-27-3 | E9: C6H18O | F9: CCCCCCO | G9: 1.3. | H9: Sigma-Aldrich | I9: 99.8% (GC) | J9: SHBC9189V | K9: 700 | L9: mL | M9: 102.17 | N9: 156 | O9: - | P9: 0.81883 | R9: - | S9: - | T9: - | U9: - | V9: - | W9: Active | AA9: octoh | AB9: 130.23 | AC9: 0.997
A10: octoh | B10: 1-octanol | C10: - | D10: 111-87-5 | E10: C8H18O | F10: CCCCCCCCO | G10: 1.2 | H10: Sigma-Aldrich | I10: 99.7% (GC) | J10: SDBB1117 | K10: 200? | L10: mL | M10: 130.23 | N10: 195 | O10: - | P10: 0.82518 | R10: - | S10: - | T10: - | U10: - | V10: - | W10: Active | AA10: mibk | AB10: 100.16 | AC10: 0.998
A11: mibk | B11: methyl isobutyl ketone | C11: MIBK | D11: 108-10-1 | E11: C6H12O | F11: CC(C)CC(=O)C | G11: 2.4 | H11: Merck Millipor | I11: 99.8% (GC) | J11: K51239346927 | K11: 300? | L11: mL | M11: 100.16 | N11: 115 | O11: - | P11: 0.80143 | R11: - | S11: - | T11: - | U11: - | V11: - | W11: Active | AA11: 2octanone | AB11: 128.21 | AC11: 0.988
A12: 2octanone | B12: 2-octanone | C12: Hexyl methyl ketone | D12: 111-13-7 | E12: C8H16O | F12: CCCCCCC(=O)C | G12: 3.2 | H12: Sigma-Aldrich | I12: 98.8% (GC) | J12: SHBQ4121 | K12: 200? | L12: mL | M12: 128.21 | N12: 173 | O12: - | P12: 0.81906 | R12: - | S12: - | T12: - | U12: - | V12: - | W12: Active | AA12: thymol | AB12: 150.22 | AC12: 0.999
A13: thymol | B13: Thymol | C13: - | D13: 89-83-8 | E13: C10H14O | F13: Cc1ccc(C(C)C)c(O)c1 | G13: 1.2 | H13: Sigma-Aldrich | I13: >99.9% (GC) | J13: SHBQ5769 | K13: 800 | L13: g | M13: 150.22 | N13: 233 | O13: - | P13: 0.96 | R13: - | S13: - | T13: - | U13: - | V13: - | W13: Active | AA13: carvone | AB13: 150.22 | AC13: 0.992
A14: carvone | B14: L-Carvone | C14: (-)-Carvone | D14: 6485-40-1 | E14: C10H14O | F14: C=C(C)[C@@H]1CC=C(C)C(=O)C1 | G14: 1.2 | H14: Sigma-Aldrich | I14: 99.2% (GC) | J14: SHBQ8402 | K14: 1 | L14: kg | M14: 150.22 | N14: 226 | O14: - | P14: 0.96 | R14: - | S14: - | T14: - | U14: - | V14: - | W14: Active | AA14: camphor | AB14: 152.24 | AC14: 0.969
A15: camphor | B15: DL-Camphor | C15: - | D15: 76-22-2 | E15: C10H16O | F15: CC1(C)C2CCC1(C)C(=O)C2 | G15: 3.2 | H15: Sigma-Aldrich | I15: 96.9% (GC) | J15: SDBB0718 | K15: 250 | L15: g | M15: 152.24 | N15: 210 | O15: - | P15: 0.99 | R15: - | S15: - | T15: - | U15: - | V15: - | W15: Active | AA15: geraniol | AB15: 154.25 | AC15: 0.989
A16: geraniol | B16: Geraniol | C16: - | D16: 106-24-1 | E16: C10H18O | F16: CC(C)=CCC/C(C)=C/CO | G16: 2.3 | H16: Sigma-Aldrich | I16: 98.9% (GC) | J16: SHBP7700 | K16: 700 | L16: g | M16: 154.25 | N16: 229 | O16: - | P16: 0.889 | R16: - | S16: - | T16: - | U16: - | V16: - | W16: Active | AA16: carvacrol | AB16: 150.22 | AC16: 0.997
A17: carvacrol | B17: Carvacrol | C17: - | D17: 499-75-2 | E17: C10H14O | F17: Cc1ccc(C(C)C)cc1O | G17: 2.1 | H17: Sigma-Aldrich | I17: 99.7% (GC) | J17: SHBQ9085 | K17: 400? | L17: mL | M17: 150.22 | N17: 239 | O17: - | P17: 0.977 | R17: - | S17: - | T17: - | U17: - | V17: - | W17: Active | AA17: eugenol | AB17: 164.2 | AC17: 0.992
A18: eugenol | B18: Eugenol | C18: - | D18: 97-53-0 | E18: C10H12O2 | F18: C=CCc1ccc(O)c(OC)c1 | G18: 1.3 | H18: Sigma-Aldrich | I18: 99.2% (GC) | J18: SHBM4053 | K18: 500? | L18: mL | M18: 164.2 | N18: 215 | O18: - | P18: 1.06 | R18: - | S18: - | T18: - | U18: - | V18: - | W18: Active
A19: h2o | B19: Water | C19: - | D19: - | E19: - | G19: - | H19: - | I19: HPLC | J19: - | K19: - | L19: - | M19: 18.02 | N19: 100 | O19: - | R19: - | S19: - | T19: - | U19: - | V19: - | W19: Active
B21: Aroma (soluto)
B22: Solventes
B23: DESs
B24: Agua (diluyente)

Sheet datos_des
B2: LLE con agua | C2: ThyCar | D2: ThyGer | E2: ThyCarvon | F2: ThyEug | G2: CamCar | H2: CamGer | I2: CamCarvac | J2: CamEug
B3: b-ionona | L3: HBA | M3: HBD
B4: 2-phenylethanol | K4: 1 | L4: Thymol | M4: Carvone | N4: 1
B5: g-decalactone | K5: 2 | L5: Camphor | M5: Geraniol | N5: 2
M6: Carvacrol | N6: 3
B7: VLE | C7: ThyCar | D7: ThyGer | E7: ThyCarvon | F7: ThyEug | G7: CamCar | H7: CamGer | I7: CamCarvac | J7: CamEug | M7: Eugenol | N7: 4
B8: b-ionona
B9: 2-phenylethanol
B10: g-decalactone
C12: Falta fleck
B14: PREPARACIÓN DES 10.00 g (1:1 molar)
B15: m_total: | C15: 10 | D15: g
B16: DES | C16: HBA | D16: MW_HBA | E16: Pureza_HBA | F16: m_HBA target (g) | G16: m_HBA exp (g) | H16: HBD | I16: MW_HBD | J16: Pureza_HBD | K16: m_HBD target (g) | L16: m_HBD exp (g) | M16: n_HBA/n_HBD
B17: ThyCar | C17: thymol | D17: =VLOOKUP(C17,Componentes!$AA$3:$AC$17,2,FALSE()) | E17: =VLOOKUP(C17,Componentes!$AA$3:$AC$17,3,FALSE()) | F17: =$C$15*D17/(D17+I17)/E17 | G17: 5.0064 | H17: carvone | I17: =VLOOKUP(H17,Componentes!$AA$3:$AC$17,2,FALSE()) | J17: =VLOOKUP(H17,Componentes!$AA$3:$AC$17,3,FALSE()) | K17: =$C$15*I17/(D17+I17)/J17 | L17: 5.0469 | M17: =IF(AND(G17<>"",L17<>""),(G17*E17/D17)/(L17*J17/I17),"")
B18: ThyGer | C18: thymol | D18: =VLOOKUP(C18,Componentes!$AA$3:$AC$17,2,FALSE()) | E18: =VLOOKUP(C18,Componentes!$AA$3:$AC$17,3,FALSE()) | F18: =$C$15*D18/(D18+I18)/E18 | G18: 4.95 | H18: geraniol | I18: =VLOOKUP(H18,Componentes!$AA$3:$AC$17,2,FALSE()) | J18: =VLOOKUP(H18,Componentes!$AA$3:$AC$17,3,FALSE()) | K18: =$C$15*I18/(D18+I18)/J18 | L18: 5.1232 | M18: =IF(AND(G18<>"",L18<>""),(G18*E18/D18)/(L18*J18/I18),"")
B19: ThyCarvac | C19: thymol | D19: =VLOOKUP(C19,Componentes!$AA$3:$AC$17,2,FALSE()) | E19: =VLOOKUP(C19,Componentes!$AA$3:$AC$17,3,FALSE()) | F19: =$C$15*D19/(D19+I19)/E19 | G19: 5.0063 | H19: carvacrol | I19: =VLOOKUP(H19,Componentes!$AA$3:$AC$17,2,FALSE()) | J19: =VLOOKUP(H19,Componentes!$AA$3:$AC$17,3,FALSE()) | K19: =$C$15*I19/(D19+I19)/J19 | L19: 5.0156 | M19: =IF(AND(G19<>"",L19<>""),(G19*E19/D19)/(L19*J19/I19),"")
B20: ThyEug | C20: thymol | D20: =VLOOKUP(C20,Componentes!$AA$3:$AC$17,2,FALSE()) | E20: =VLOOKUP(C20,Componentes!$AA$3:$AC$17,3,FALSE()) | F20: =$C$15*D20/(D20+I20)/E20 | G20: 4.7931 | H20: eugenol | I20: =VLOOKUP(H20,Componentes!$AA$3:$AC$17,2,FALSE()) | J20: =VLOOKUP(H20,Componentes!$AA$3:$AC$17,3,FALSE()) | K20: =$C$15*I20/(D20+I20)/J20 | L20: 5.2668 | M20: =IF(AND(G20<>"",L20<>""),(G20*E20/D20)/(L20*J20/I20),"")
B21: ThyCam | C21: thymol | D21: =VLOOKUP(C21,Componentes!$AA$3:$AC$17,2,FALSE()) | E21: =VLOOKUP(C21,Componentes!$AA$3:$AC$17,3,FALSE()) | F21: =$C$15*D21/(D21+I21)/E21 | G21: =1.6711+1.6663+1.6953 | H21: camphor | I21: =VLOOKUP(H21,Componentes!$AA$3:$AC$17,2,FALSE()) | J21: =VLOOKUP(H21,Componentes!$AA$3:$AC$17,3,FALSE()) | K21: =$C$15*I21/(D21+I21)/J21 | L21: =1.7344+1.7354+1.7709 | M21: =IF(AND(G21<>"",L21<>""),(G21*E21/D21)/(L21*J21/I21),"")
B22: CamCar | C22: camphor | D22: =VLOOKUP(C22,Componentes!$AA$3:$AC$17,2,FALSE()) | E22: =VLOOKUP(C22,Componentes!$AA$3:$AC$17,3,FALSE()) | F22: =$C$15*D22/(D22+I22)/E22 | G22: 5.2014 | H22: carvone | I22: =VLOOKUP(H22,Componentes!$AA$3:$AC$17,2,FALSE()) | J22: =VLOOKUP(H22,Componentes!$AA$3:$AC$17,3,FALSE()) | K22: =$C$15*I22/(D22+I22)/J22 | L22: 5.0074 | M22: =IF(AND(G22<>"",L22<>""),(G22*E22/D22)/(L22*J22/I22),"")
B23: CamGer | C23: camphor | D23: =VLOOKUP(C23,Componentes!$AA$3:$AC$17,2,FALSE()) | E23: =VLOOKUP(C23,Componentes!$AA$3:$AC$17,3,FALSE()) | F23: =$C$15*D23/(D23+I23)/E23 | G23: 5.1236 | H23: geraniol | I23: =VLOOKUP(H23,Componentes!$AA$3:$AC$17,2,FALSE()) | J23: =VLOOKUP(H23,Componentes!$AA$3:$AC$17,3,FALSE()) | K23: =$C$15*I23/(D23+I23)/J23 | L23: 5.084 | M23: =IF(AND(G23<>"",L23<>""),(G23*E23/D23)/(L23*J23/I23),"")
B24: CamCarvac | C24: camphor | D24: =VLOOKUP(C24,Componentes!$AA$3:$AC$17,2,FALSE()) | E24: =VLOOKUP(C24,Componentes!$AA$3:$AC$17,3,FALSE()) | F24: =$C$15*D24/(D24+I24)/E24 | G24: 5.1992 | H24: carvacrol | I24: =VLOOKUP(H24,Componentes!$AA$3:$AC$17,2,FALSE()) | J24: =VLOOKUP(H24,Componentes!$AA$3:$AC$17,3,FALSE()) | K24: =$C$15*I24/(D24+I24)/J24 | L24: 4.9816 | M24: =IF(AND(G24<>"",L24<>""),(G24*E24/D24)/(L24*J24/I24),"")
B25: CamEug | C25: camphor | D25: =VLOOKUP(C25,Componentes!$AA$3:$AC$17,2,FALSE()) | E25: =VLOOKUP(C25,Componentes!$AA$3:$AC$17,3,FALSE()) | F25: =$C$15*D25/(D25+I25)/E25 | G25: 4.9655 | H25: eugenol | I25: =VLOOKUP(H25,Componentes!$AA$3:$AC$17,2,FALSE()) | J25: =VLOOKUP(H25,Componentes!$AA$3:$AC$17,3,FALSE()) | K25: =$C$15*I25/(D25+I25)/J25 | L25: 5.2307 | M25: =IF(AND(G25<>"",L25<>""),(G25*E25/D25)/(L25*J25/I25),"")
B27: Amarillo: ingreso experimental | E27: Verde: calculado desde Componentes

Sheet 2-phenylethanol_DES
A1: LLE Ternario: 2-phenylethanol + DES + Water
A2: Target mass (g): | B2: 7 | C2: ← change here to rescale all masses
A3: Yellow = paste z (mass fracs) from software | Green = auto-calculated
A5: # | B5: DES | C5: HBA | D5: HBD | E5: Ratio | F5: TL# | G5: z_aroma | H5: z_DES | I5: z_water | J5: Σz (check) | K5: m_aroma (g) | L5: m_DES (g) | M5: m_water (g) | N5: m_total (g)
A6: 1 | B6: ThyCar | C6: Thymol | D6: Carvone | E6: 1:1 | F6: 1 | G6: 0.02048 | H6: 0.47645 | I6: 0.50307 | J6: =IF(G6="","",G6+H6+I6) | K6: =IF(G6="","",G6*$B$2) | L6: =IF(H6="","",H6*$B$2) | M6: =IF(I6="","",I6*$B$2) | N6: =IF(K6="","",K6+L6+M6)
A7: 2 | E7: 1:1 | F7: 2 | G7: 0.47529 | H7: 0.02048 | I7: 0.50422 | J7: =IF(G7="","",G7+H7+I7) | K7: =IF(G7="","",G7*$B$2) | L7: =IF(H7="","",H7*$B$2) | M7: =IF(I7="","",I7*$B$2) | N7: =IF(K7="","",K7+L7+M7)
A8: 3 | E8: 1:1 | F8: 3 | G8: 0.24503 | H8: 0.25452 | I8: 0.50045 | J8: =IF(G8="","",G8+H8+I8) | K8: =IF(G8="","",G8*$B$2) | L8: =IF(H8="","",H8*$B$2) | M8: =IF(I8="","",I8*$B$2) | N8: =IF(K8="","",K8+L8+M8)
A9: 4 | E9: 1:1 | F9: 4 | G9: 0.13276 | H9: 0.36622 | I9: 0.50102 | J9: =IF(G9="","",G9+H9+I9) | K9: =IF(G9="","",G9*$B$2) | L9: =IF(H9="","",H9*$B$2) | M9: =IF(I9="","",I9*$B$2) | N9: =IF(K9="","",K9+L9+M9)
A10: 5 | E10: 1:1 | F10: 5 | G10: 0.35944 | H10: 0.13914 | I10: 0.50142 | J10: =IF(G10="","",G10+H10+I10) | K10: =IF(G10="","",G10*$B$2) | L10: =IF(H10="","",H10*$B$2) | M10: =IF(I10="","",I10*$B$2) | N10: =IF(K10="","",K10+L10+M10)
A12: 6 | B12: ThyGer | C12: Thymol | D12: Geraniol | E12: 1:1 | F12: 1 | G12: 0.47452 | H12: 0.02001 | I12: 0.50547 | J12: =IF(G12="","",G12+H12+I12) | K12: =IF(G12="","",G12*$B$2) | L12: =IF(H12="","",H12*$B$2) | M12: =IF(I12="","",I12*$B$2) | N12: =IF(K12="","",K12+L12+M12)
A13: 7 | E13: 1:1 | F13: 2 | G13: 0.02072 | H13: 0.45539 | I13: 0.52389 | J13: =IF(G13="","",G13+H13+I13) | K13: =IF(G13="","",G13*$B$2) | L13: =IF(H13="","",H13*$B$2) | M13: =IF(I13="","",I13*$B$2) | N13: =IF(K13="","",K13+L13+M13)
A14: 8 | E14: 1:1 | F14: 3 | G14: 0.24795 | H14: 0.23883 | I14: 0.51322 | J14: =IF(G14="","",G14+H14+I14) | K14: =IF(G14="","",G14*$B$2) | L14: =IF(H14="","",H14*$B$2) | M14: =IF(I14="","",I14*$B$2) | N14: =IF(K14="","",K14+L14+M14)
A15: 9 | E15: 1:1 | F15: 4 | G15: 0.13477 | H15: 0.34704 | I15: 0.51819 | J15: =IF(G15="","",G15+H15+I15) | K15: =IF(G15="","",G15*$B$2) | L15: =IF(H15="","",H15*$B$2) | M15: =IF(I15="","",I15*$B$2) | N15: =IF(K15="","",K15+L15+M15)
A16: 10 | E16: 1:1 | F16: 5 | G16: 0.36056 | H16: 0.13046 | I16: 0.50898 | J16: =IF(G16="","",G16+H16+I16) | K16: =IF(G16="","",G16*$B$2) | L16: =IF(H16="","",H16*$B$2) | M16: =IF(I16="","",I16*$B$2) | N16: =IF(K16="","",K16+L16+M16)
A18: 11 | B18: ThyCarvac | C18: Thymol | D18: Carvacrol | E18: 1:1 | F18: 1 | G18: 0.47439 | H18: 0.02051 | I18: 0.5051 | J18: =IF(G18="","",G18+H18+I18) | K18: =IF(G18="","",G18*$B$2) | L18: =IF(H18="","",H18*$B$2) | M18: =IF(I18="","",I18*$B$2) | N18: =IF(K18="","",K18+L18+M18)
A19: 12 | E19: 1:1 | F19: 2 | G19: 0.02032 | H19: 0.46755 | I19: 0.51214 | J19: =IF(G19="","",G19+H19+I19) | K19: =IF(G19="","",G19*$B$2) | L19: =IF(H19="","",H19*$B$2) | M19: =IF(I19="","",I19*$B$2) | N19: =IF(K19="","",K19+L19+M19)
A20: 13 | E20: 1:1 | F20: 3 | G20: 0.2465 | H20: 0.24556 | I20: 0.50794 | J20: =IF(G20="","",G20+H20+I20) | K20: =IF(G20="","",G20*$B$2) | L20: =IF(H20="","",H20*$B$2) | M20: =IF(I20="","",I20*$B$2) | N20: =IF(K20="","",K20+L20+M20)
A21: 14 | E21: 1:1 | F21: 4 | G21: 0.1329 | H21: 0.35721 | I21: 0.50989 | J21: =IF(G21="","",G21+H21+I21) | K21: =IF(G21="","",G21*$B$2) | L21: =IF(H21="","",H21*$B$2) | M21: =IF(I21="","",I21*$B$2) | N21: =IF(K21="","",K21+L21+M21)
A22: 15 | E22: 1:1 | F22: 5 | G22: 0.35977 | H22: 0.1339 | I22: 0.50634 | J22: =IF(G22="","",G22+H22+I22) | K22: =IF(G22="","",G22*$B$2) | L22: =IF(H22="","",H22*$B$2) | M22: =IF(I22="","",I22*$B$2) | N22: =IF(K22="","",K22+L22+M22)
A24: 16 | B24: ThyEug | C24: Thymol | D24: Eugenol | E24: 1:1 | F24: 1 | G24: 0.47573 | H24: 0.02001 | I24: 0.50426 | J24: =IF(G24="","",G24+H24+I24) | K24: =IF(G24="","",G24*$B$2) | L24: =IF(H24="","",H24*$B$2) | M24: =IF(I24="","",I24*$B$2) | N24: =IF(K24="","",K24+L24+M24)
A25: 17 | E25: 1:1 | F25: 2 | G25: 0.02082 | H25: 0.47311 | I25: 0.50606 | J25: =IF(G25="","",G25+H25+I25) | K25: =IF(G25="","",G25*$B$2) | L25: =IF(H25="","",H25*$B$2) | M25: =IF(I25="","",I25*$B$2) | N25: =IF(K25="","",K25+L25+M25)
A26: 18 | E26: 1:1 | F26: 3 | G26: 0.24474 | H26: 0.25403 | I26: 0.50124 | J26: =IF(G26="","",G26+H26+I26) | K26: =IF(G26="","",G26*$B$2) | L26: =IF(H26="","",H26*$B$2) | M26: =IF(I26="","",I26*$B$2) | N26: =IF(K26="","",K26+L26+M26)
A27: 19 | E27: 1:1 | F27: 4 | G27: 0.35862 | H27: 0.13975 | I27: 0.50163 | J27: =IF(G27="","",G27+H27+I27) | K27: =IF(G27="","",G27*$B$2) | L27: =IF(H27="","",H27*$B$2) | M27: =IF(I27="","",I27*$B$2) | N27: =IF(K27="","",K27+L27+M27)
A28: 20 | E28: 1:1 | F28: 5 | G28: 0.13271 | H28: 0.36448 | I28: 0.50281 | J28: =IF(G28="","",G28+H28+I28) | K28: =IF(G28="","",G28*$B$2) | L28: =IF(H28="","",H28*$B$2) | M28: =IF(I28="","",I28*$B$2) | N28: =IF(K28="","",K28+L28+M28)
A30: 21 | B30: ThyCam | C30: Thymol | D30: Camphor | E30: 1:1 | F30: 1 | G30: 0.0203 | H30: 0.47651 | I30: 0.50319 | J30: =IF(G30="","",G30+H30+I30) | K30: =IF(G30="","",G30*$B$2) | L30: =IF(H30="","",H30*$B$2) | M30: =IF(I30="","",I30*$B$2) | N30: =IF(K30="","",K30+L30+M30)
A31: 22 | E31: 1:1 | F31: 2 | G31: 0.47512 | H31: 0.02061 | I31: 0.50426 | J31: =IF(G31="","",G31+H31+I31) | K31: =IF(G31="","",G31*$B$2) | L31: =IF(H31="","",H31*$B$2) | M31: =IF(I31="","",I31*$B$2) | N31: =IF(K31="","",K31+L31+M31)
A32: 23 | E32: 1:1 | F32: 3 | G32: 0.24476 | H32: 0.25451 | I32: 0.50073 | J32: =IF(G32="","",G32+H32+I32) | K32: =IF(G32="","",G32*$B$2) | L32: =IF(H32="","",H32*$B$2) | M32: =IF(I32="","",I32*$B$2) | N32: =IF(K32="","",K32+L32+M32)
A33: 24 | E33: 1:1 | F33: 4 | G33: 0.13232 | H33: 0.36642 | I33: 0.50126 | J33: =IF(G33="","",G33+H33+I33) | K33: =IF(G33="","",G33*$B$2) | L33: =IF(H33="","",H33*$B$2) | M33: =IF(I33="","",I33*$B$2) | N33: =IF(K33="","",K33+L33+M33)
A34: 25 | E34: 1:1 | F34: 5 | G34: 0.35859 | H34: 0.13977 | I34: 0.50163 | J34: =IF(G34="","",G34+H34+I34) | K34: =IF(G34="","",G34*$B$2) | L34: =IF(H34="","",H34*$B$2) | M34: =IF(I34="","",I34*$B$2) | N34: =IF(K34="","",K34+L34+M34)
A36: 26 | B36: CamCar | C36: Camphor | D36: Carvone | E36: 1:1 | F36: 1 | G36: 0.02055 | H36: 0.48113 | I36: 0.49832 | J36: =IF(G36="","",G36+H36+I36) | K36: =IF(G36="","",G36*$B$2) | L36: =IF(H36="","",H36*$B$2) | M36: =IF(I36="","",I36*$B$2) | N36: =IF(K36="","",K36+L36+M36)
A37: 27 | E37: 1:1 | F37: 2 | G37: 0.476 | H37: 0.02061 | I37: 0.50339 | J37: =IF(G37="","",G37+H37+I37) | K37: =IF(G37="","",G37*$B$2) | L37: =IF(H37="","",H37*$B$2) | M37: =IF(I37="","",I37*$B$2) | N37: =IF(K37="","",K37+L37+M37)
A38: 28 | E38: 1:1 | F38: 3 | G38: 0.24392 | H38: 0.26133 | I38: 0.49475 | J38: =IF(G38="","",G38+H38+I38) | K38: =IF(G38="","",G38*$B$2) | L38: =IF(H38="","",H38*$B$2) | M38: =IF(I38="","",I38*$B$2) | N38: =IF(K38="","",K38+L38+M38)
A39: 29 | E39: 1:1 | F39: 4 | G39: 0.35809 | H39: 0.14474 | I39: 0.49717 | J39: =IF(G39="","",G39+H39+I39) | K39: =IF(G39="","",G39*$B$2) | L39: =IF(H39="","",H39*$B$2) | M39: =IF(I39="","",I39*$B$2) | N39: =IF(K39="","",K39+L39+M39)
A40: 30 | E40: 1:1 | F40: 5 | G40: 0.13213 | H40: 0.37292 | I40: 0.49495 | J40: =IF(G40="","",G40+H40+I40) | K40: =IF(G40="","",G40*$B$2) | L40: =IF(H40="","",H40*$B$2) | M40: =IF(I40="","",I40*$B$2) | N40: =IF(K40="","",K40+L40+M40)
A42: 31 | B42: CamGer | C42: Camphor | D42: Geraniol | E42: 1:1 | F42: 1 | G42: 0.02003 | H42: 0.4642 | I42: 0.51577 | J42: =IF(G42="","",G42+H42+I42) | K42: =IF(G42="","",G42*$B$2) | L42: =IF(H42="","",H42*$B$2) | M42: =IF(I42="","",I42*$B$2) | N42: =IF(K42="","",K42+L42+M42)
A43: 32 | E43: 1:1 | F43: 2 | G43: 0.47522 | H43: 0.02013 | I43: 0.50465 | J43: =IF(G43="","",G43+H43+I43) | K43: =IF(G43="","",G43*$B$2) | L43: =IF(H43="","",H43*$B$2) | M43: =IF(I43="","",I43*$B$2) | N43: =IF(K43="","",K43+L43+M43)
A44: 33 | E44: 1:1 | F44: 3 | G44: 0.24608 | H44: 0.24734 | I44: 0.50658 | J44: =IF(G44="","",G44+H44+I44) | K44: =IF(G44="","",G44*$B$2) | L44: =IF(H44="","",H44*$B$2) | M44: =IF(I44="","",I44*$B$2) | N44: =IF(K44="","",K44+L44+M44)
A45: 34 | E45: 1:1 | F45: 4 | G45: 0.35967 | H45: 0.13575 | I45: 0.50458 | J45: =IF(G45="","",G45+H45+I45) | K45: =IF(G45="","",G45*$B$2) | L45: =IF(H45="","",H45*$B$2) | M45: =IF(I45="","",I45*$B$2) | N45: =IF(K45="","",K45+L45+M45)
A46: 35 | E46: 1:1 | F46: 5 | G46: 0.13286 | H46: 0.35682 | I46: 0.51032 | J46: =IF(G46="","",G46+H46+I46) | K46: =IF(G46="","",G46*$B$2) | L46: =IF(H46="","",H46*$B$2) | M46: =IF(I46="","",I46*$B$2) | N46: =IF(K46="","",K46+L46+M46)
A48: 36 | B48: CamCarvac | C48: Camphor | D48: Carvacrol | E48: 1:1 | F48: 1 | G48: 0.02035 | H48: 0.47845 | I48: 0.5012 | J48: =IF(G48="","",G48+H48+I48) | K48: =IF(G48="","",G48*$B$2) | L48: =IF(H48="","",H48*$B$2) | M48: =IF(I48="","",I48*$B$2) | N48: =IF(K48="","",K48+L48+M48)
...

Sheet Lab_Solventes
A1: LAB SHEET — 2-phenylethanol + Solvent + Water
A2: Add in order: tube → water → aroma → solvent. Record cumulative balance reading after each addition.
A4: ρ_aroma (g/mL): | B4: =Componentes!P4 | C4: 2-phenylethanol
A5: ρ_water (g/mL): | B5: 0.997
B7: Pipetting guide (from predictions) | F7: Record on balance | J7: Auto-calculated by difference
A9: # | B9: Solvent | C9: TL# | D9: V_water est (mL) | E9: V_aroma est (mL) | F9: V_solv est (mL) | G9: W_tube (g) | H9: W +water (g) | I9: W +aroma (g) | J9: W +solv (g) | K9: m_water (g) | L9: m_aroma (g) | M9: m_solvent (g) | N9: m_total (g) | O9: w_water | P9: w_aroma | Q9: w_solvent | R9: Notes
A10: 1 | B10: 2m3b2oh | C10: 1 | D10: =IF(predicciones_pcsaft!E6="","",predicciones_pcsaft!E6*7/$B$5) | E10: =IF(predicciones_pcsaft!C6="","",predicciones_pcsaft!C6*7/$B$4) | F10: =IF(predicciones_pcsaft!D6="","",predicciones_pcsaft!D6*7/Componentes!P6) | K10: =IF(OR(G10="",H10=""),"",H10-G10) | L10: =IF(OR(H10="",I10=""),"",I10-H10) | M10: =IF(OR(I10="",J10=""),"",J10-I10) | N10: =IF(OR(G10="",J10=""),"",J10-G10) | O10: =IF(N10="","",K10/N10) | P10: =IF(N10="","",L10/N10) | Q10: =IF(N10="","",M10/N10)
A11: 2 | C11: 2 | D11: =IF(predicciones_pcsaft!E7="","",predicciones_pcsaft!E7*7/$B$5) | E11: =IF(predicciones_pcsaft!C7="","",predicciones_pcsaft!C7*7/$B$4) | F11: =IF(predicciones_pcsaft!D7="","",predicciones_pcsaft!D7*7/Componentes!P6) | K11: =IF(OR(G11="",H11=""),"",H11-G11) | L11: =IF(OR(H11="",I11=""),"",I11-H11) | M11: =IF(OR(I11="",J11=""),"",J11-I11) | N11: =IF(OR(G11="",J11=""),"",J11-G11) | O11: =IF(N11="","",K11/N11) | P11: =IF(N11="","",L11/N11) | Q11: =IF(N11="","",M11/N11)
A12: 3 | C12: 3 | D12: =IF(predicciones_pcsaft!E8="","",predicciones_pcsaft!E8*7/$B$5) | E12: =IF(predicciones_pcsaft!C8="","",predicciones_pcsaft!C8*7/$B$4) | F12: =IF(predicciones_pcsaft!D8="","",predicciones_pcsaft!D8*7/Componentes!P6) | K12: =IF(OR(G12="",H12=""),"",H12-G12) | L12: =IF(OR(H12="",I12=""),"",I12-H12) | M12: =IF(OR(I12="",J12=""),"",J12-I12) | N12: =IF(OR(G12="",J12=""),"",J12-G12) | O12: =IF(N12="","",K12/N12) | P12: =IF(N12="","",L12/N12) | Q12: =IF(N12="","",M12/N12)
A13: 4 | C13: 4 | D13: =IF(predicciones_pcsaft!E9="","",predicciones_pcsaft!E9*7/$B$5) | E13: =IF(predicciones_pcsaft!C9="","",predicciones_pcsaft!C9*7/$B$4) | F13: =IF(predicciones_pcsaft!D9="","",predicciones_pcsaft!D9*7/Componentes!P6) | K13: =IF(OR(G13="",H13=""),"",H13-G13) | L13: =IF(OR(H13="",I13=""),"",I13-H13) | M13: =IF(OR(I13="",J13=""),"",J13-I13) | N13: =IF(OR(G13="",J13=""),"",J13-G13) | O13: =IF(N13="","",K13/N13) | P13: =IF(N13="","",L13/N13) | Q13: =IF(N13="","",M13/N13)
A14: 5 | C14: 5 | D14: =IF(predicciones_pcsaft!E10="","",predicciones_pcsaft!E10*7/$B$5) | E14: =IF(predicciones_pcsaft!C10="","",predicciones_pcsaft!C10*7/$B$4) | F14: =IF(predicciones_pcsaft!D10="","",predicciones_pcsaft!D10*7/Componentes!P6) | K14: =IF(OR(G14="",H14=""),"",H14-G14) | L14: =IF(OR(H14="",I14=""),"",I14-H14) | M14: =IF(OR(I14="",J14=""),"",J14-I14) | N14: =IF(OR(G14="",J14=""),"",J14-G14) | O14: =IF(N14="","",K14/N14) | P14: =IF(N14="","",L14/N14) | Q14: =IF(N14="","",M14/N14)
A16: 6 | B16: 2m2boh | C16: 1 | D16: =IF(predicciones_pcsaft!E12="","",predicciones_pcsaft!E12*7/$B$5) | E16: =IF(predicciones_pcsaft!C12="","",predicciones_pcsaft!C12*7/$B$4) | F16: =IF(predicciones_pcsaft!D12="","",predicciones_pcsaft!D12*7/Componentes!P7) | K16: =IF(OR(G16="",H16=""),"",H16-G16) | L16: =IF(OR(H16="",I16=""),"",I16-H16) | M16: =IF(OR(I16="",J16=""),"",J16-I16) | N16: =IF(OR(G16="",J16=""),"",J16-G16) | O16: =IF(N16="","",K16/N16) | P16: =IF(N16="","",L16/N16) | Q16: =IF(N16="","",M16/N16)
A17: 7 | C17: 2 | D17: =IF(predicciones_pcsaft!E13="","",predicciones_pcsaft!E13*7/$B$5) | E17: =IF(predicciones_pcsaft!C13="","",predicciones_pcsaft!C13*7/$B$4) | F17: =IF(predicciones_pcsaft!D13="","",predicciones_pcsaft!D13*7/Componentes!P7) | K17: =IF(OR(G17="",H17=""),"",H17-G17) | L17: =IF(OR(H17="",I17=""),"",I17-H17) | M17: =IF(OR(I17="",J17=""),"",J17-I17) | N17: =IF(OR(G17="",J17=""),"",J17-G17) | O17: =IF(N17="","",K17/N17) | P17: =IF(N17="","",L17/N17) | Q17: =IF(N17="","",M17/N17)
A18: 8 | C18: 3 | D18: =IF(predicciones_pcsaft!E14="","",predicciones_pcsaft!E14*7/$B$5) | E18: =IF(predicciones_pcsaft!C14="","",predicciones_pcsaft!C14*7/$B$4) | F18: =IF(predicciones_pcsaft!D14="","",predicciones_pcsaft!D14*7/Componentes!P7) | K18: =IF(OR(G18="",H18=""),"",H18-G18) | L18: =IF(OR(H18="",I18=""),"",I18-H18) | M18: =IF(OR(I18="",J18=""),"",J18-I18) | N18: =IF(OR(G18="",J18=""),"",J18-G18) | O18: =IF(N18="","",K18/N18) | P18: =IF(N18="","",L18/N18) | Q18: =IF(N18="","",M18/N18)
A19: 9 | C19: 4 | D19: =IF(predicciones_pcsaft!E15="","",predicciones_pcsaft!E15*7/$B$5) | E19: =IF(predicciones_pcsaft!C15="","",predicciones_pcsaft!C15*7/$B$4) | F19: =IF(predicciones_pcsaft!D15="","",predicciones_pcsaft!D15*7/Componentes!P7) | K19: =IF(OR(G19="",H19=""),"",H19-G19) | L19: =IF(OR(H19="",I19=""),"",I19-H19) | M19: =IF(OR(I19="",J19=""),"",J19-I19) | N19: =IF(OR(G19="",J19=""),"",J19-G19) | O19: =IF(N19="","",K19/N19) | P19: =IF(N19="","",L19/N19) | Q19: =IF(N19="","",M19/N19)
A20: 10 | C20: 5 | D20: =IF(predicciones_pcsaft!E16="","",predicciones_pcsaft!E16*7/$B$5) | E20: =IF(predicciones_pcsaft!C16="","",predicciones_pcsaft!C16*7/$B$4) | F20: =IF(predicciones_pcsaft!D16="","",predicciones_pcsaft!D16*7/Componentes!P7) | K20: =IF(OR(G20="",H20=""),"",H20-G20) | L20: =IF(OR(H20="",I20=""),"",I20-H20) | M20: =IF(OR(I20="",J20=""),"",J20-I20) | N20: =IF(OR(G20="",J20=""),"",J20-G20) | O20: =IF(N20="","",K20/N20) | P20: =IF(N20="","",L20/N20) | Q20: =IF(N20="","",M20/N20)
A22: 11 | B22: hexoh | C22: 1 | D22: =IF(predicciones_pcsaft!E18="","",predicciones_pcsaft!E18*7/$B$5) | E22: =IF(predicciones_pcsaft!C18="","",predicciones_pcsaft!C18*7/$B$4) | F22: =IF(predicciones_pcsaft!D18="","",predicciones_pcsaft!D18*7/Componentes!P8) | K22: =IF(OR(G22="",H22=""),"",H22-G22) | L22: =IF(OR(H22="",I22=""),"",I22-H22) | M22: =IF(OR(I22="",J22=""),"",J22-I22) | N22: =IF(OR(G22="",J22=""),"",J22-G22) | O22: =IF(N22="","",K22/N22) | P22: =IF(N22="","",L22/N22) | Q22: =IF(N22="","",M22/N22)
A23: 12 | C23: 2 | D23: =IF(predicciones_pcsaft!E19="","",predicciones_pcsaft!E19*7/$B$5) | E23: =IF(predicciones_pcsaft!C19="","",predicciones_pcsaft!C19*7/$B$4) | F23: =IF(predicciones_pcsaft!D19="","",predicciones_pcsaft!D19*7/Componentes!P8) | K23: =IF(OR(G23="",H23=""),"",H23-G23) | L23: =IF(OR(H23="",I23=""),"",I23-H23) | M23: =IF(OR(I23="",J23=""),"",J23-I23) | N23: =IF(OR(G23="",J23=""),"",J23-G23) | O23: =IF(N23="","",K23/N23) | P23: =IF(N23="","",L23/N23) | Q23: =IF(N23="","",M23/N23)
A24: 13 | C24: 3 | D24: =IF(predicciones_pcsaft!E20="","",predicciones_pcsaft!E20*7/$B$5) | E24: =IF(predicciones_pcsaft!C20="","",predicciones_pcsaft!C20*7/$B$4) | F24: =IF(predicciones_pcsaft!D20="","",predicciones_pcsaft!D20*7/Componentes!P8) | K24: =IF(OR(G24="",H24=""),"",H24-G24) | L24: =IF(OR(H24="",I24=""),"",I24-H24) | M24: =IF(OR(I24="",J24=""),"",J24-I24) | N24: =IF(OR(G24="",J24=""),"",J24-G24) | O24: =IF(N24="","",K24/N24) | P24: =IF(N24="","",L24/N24) | Q24: =IF(N24="","",M24/N24)
A25: 14 | C25: 4 | D25: =IF(predicciones_pcsaft!E21="","",predicciones_pcsaft!E21*7/$B$5) | E25: =IF(predicciones_pcsaft!C21="","",predicciones_pcsaft!C21*7/$B$4) | F25: =IF(predicciones_pcsaft!D21="","",predicciones_pcsaft!D21*7/Componentes!P8) | K25: =IF(OR(G25="",H25=""),"",H25-G25) | L25: =IF(OR(H25="",I25=""),"",I25-H25) | M25: =IF(OR(I25="",J25=""),"",J25-I25) | N25: =IF(OR(G25="",J25=""),"",J25-G25) | O25: =IF(N25="","",K25/N25) | P25: =IF(N25="","",L25/N25) | Q25: =IF(N25="","",M25/N25)
A26: 15 | C26: 5 | D26: =IF(predicciones_pcsaft!E22="","",predicciones_pcsaft!E22*7/$B$5) | E26: =IF(predicciones_pcsaft!C22="","",predicciones_pcsaft!C22*7/$B$4) | F26: =IF(predicciones_pcsaft!D22="","",predicciones_pcsaft!D22*7/Componentes!P8) | K26: =IF(OR(G26="",H26=""),"",H26-G26) | L26: =IF(OR(H26="",I26=""),"",I26-H26) | M26: =IF(OR(I26="",J26=""),"",J26-I26) | N26: =IF(OR(G26="",J26=""),"",J26-G26) | O26: =IF(N26="","",K26/N26) | P26: =IF(N26="","",L26/N26) | Q26: =IF(N26="","",M26/N26)
A28: 16 | B28: octoh | C28: 1 | D28: =IF(predicciones_pcsaft!E24="","",predicciones_pcsaft!E24*7/$B$5) | E28: =IF(predicciones_pcsaft!C24="","",predicciones_pcsaft!C24*7/$B$4) | F28: =IF(predicciones_pcsaft!D24="","",predicciones_pcsaft!D24*7/Componentes!P9) | K28: =IF(OR(G28="",H28=""),"",H28-G28) | L28: =IF(OR(H28="",I28=""),"",I28-H28) | M28: =IF(OR(I28="",J28=""),"",J28-I28) | N28: =IF(OR(G28="",J28=""),"",J28-G28) | O28: =IF(N28="","",K28/N28) | P28: =IF(N28="","",L28/N28) | Q28: =IF(N28="","",M28/N28)
A29: 17 | C29: 2 | D29: =IF(predicciones_pcsaft!E25="","",predicciones_pcsaft!E25*7/$B$5) | E29: =IF(predicciones_pcsaft!C25="","",predicciones_pcsaft!C25*7/$B$4) | F29: =IF(predicciones_pcsaft!D25="","",predicciones_pcsaft!D25*7/Componentes!P9) | K29: =IF(OR(G29="",H29=""),"",H29-G29) | L29: =IF(OR(H29="",I29=""),"",I29-H29) | M29: =IF(OR(I29="",J29=""),"",J29-I29) | N29: =IF(OR(G29="",J29=""),"",J29-G29) | O29: =IF(N29="","",K29/N29) | P29: =IF(N29="","",L29/N29) | Q29: =IF(N29="","",M29/N29)
A30: 18 | C30: 3 | D30: =IF(predicciones_pcsaft!E26="","",predicciones_pcsaft!E26*7/$B$5) | E30: =IF(predicciones_pcsaft!C26="","",predicciones_pcsaft!C26*7/$B$4) | F30: =IF(predicciones_pcsaft!D26="","",predicciones_pcsaft!D26*7/Componentes!P9) | K30: =IF(OR(G30="",H30=""),"",H30-G30) | L30: =IF(OR(H30="",I30=""),"",I30-H30) | M30: =IF(OR(I30="",J30=""),"",J30-I30) | N30: =IF(OR(G30="",J30=""),"",J30-G30) | O30: =IF(N30="","",K30/N30) | P30: =IF(N30="","",L30/N30) | Q30: =IF(N30="","",M30/N30)
A31: 19 | C31: 4 | D31: =IF(predicciones_pcsaft!E27="","",predicciones_pcsaft!E27*7/$B$5) | E31: =IF(predicciones_pcsaft!C27="","",predicciones_pcsaft!C27*7/$B$4) | F31: =IF(predicciones_pcsaft!D27="","",predicciones_pcsaft!D27*7/Componentes!P9) | K31: =IF(OR(G31="",H31=""),"",H31-G31) | L31: =IF(OR(H31="",I31=""),"",I31-H31) | M31: =IF(OR(I31="",J31=""),"",J31-I31) | N31: =IF(OR(G31="",J31=""),"",J31-G31) | O31: =IF(N31="","",K31/N31) | P31: =IF(N31="","",L31/N31) | Q31: =IF(N31="","",M31/N31)
A32: 20 | C32: 5 | D32: =IF(predicciones_pcsaft!E28="","",predicciones_pcsaft!E28*7/$B$5) | E32: =IF(predicciones_pcsaft!C28="","",predicciones_pcsaft!C28*7/$B$4) | F32: =IF(predicciones_pcsaft!D28="","",predicciones_pcsaft!D28*7/Componentes!P9) | K32: =IF(OR(G32="",H32=""),"",H32-G32) | L32: =IF(OR(H32="",I32=""),"",I32-H32) | M32: =IF(OR(I32="",J32=""),"",J32-I32) | N32: =IF(OR(G32="",J32=""),"",J32-G32) | O32: =IF(N32="","",K32/N32) | P32: =IF(N32="","",L32/N32) | Q32: =IF(N32="","",M32/N32)
A34: 21 | B34: mibk | C34: 1 | D34: =IF(predicciones_pcsaft!E30="","",predicciones_pcsaft!E30*7/$B$5) | E34: =IF(predicciones_pcsaft!C30="","",predicciones_pcsaft!C30*7/$B$4) | F34: =IF(predicciones_pcsaft!D30="","",predicciones_pcsaft!D30*7/Componentes!P10) | K34: =IF(OR(G34="",H34=""),"",H34-G34) | L34: =IF(OR(H34="",I34=""),"",I34-H34) | M34: =IF(OR(I34="",J34=""),"",J34-I34) | N34: =IF(OR(G34="",J34=""),"",J34-G34) | O34: =IF(N34="","",K34/N34) | P34: =IF(N34="","",L34/N34) | Q34: =IF(N34="","",M34/N34)
A35: 22 | C35: 2 | D35: =IF(predicciones_pcsaft!E31="","",predicciones_pcsaft!E31*7/$B$5) | E35: =IF(predicciones_pcsaft!C31="","",predicciones_pcsaft!C31*7/$B$4) | F35: =IF(predicciones_pcsaft!D31="","",predicciones_pcsaft!D31*7/Componentes!P10) | K35: =IF(OR(G35="",H35=""),"",H35-G35) | L35: =IF(OR(H35="",I35=""),"",I35-H35) | M35: =IF(OR(I35="",J35=""),"",J35-I35) | N35: =IF(OR(G35="",J35=""),"",J35-G35) | O35: =IF(N35="","",K35/N35) | P35: =IF(N35="","",L35/N35) | Q35: =IF(N35="","",M35/N35)
A36: 23 | C36: 3 | D36: =IF(predicciones_pcsaft!E32="","",predicciones_pcsaft!E32*7/$B$5) | E36: =IF(predicciones_pcsaft!C32="","",predicciones_pcsaft!C32*7/$B$4) | F36: =IF(predicciones_pcsaft!D32="","",predicciones_pcsaft!D32*7/Componentes!P10) | K36: =IF(OR(G36="",H36=""),"",H36-G36) | L36: =IF(OR(H36="",I36=""),"",I36-H36) | M36: =IF(OR(I36="",J36=""),"",J36-I36) | N36: =IF(OR(G36="",J36=""),"",J36-G36) | O36: =IF(N36="","",K36/N36) | P36: =IF(N36="","",L36/N36) | Q36: =IF(N36="","",M36/N36)
A37: 24 | C37: 4 | D37: =IF(predicciones_pcsaft!E33="","",predicciones_pcsaft!E33*7/$B$5) | E37: =IF(predicciones_pcsaft!C33="","",predicciones_pcsaft!C33*7/$B$4) | F37: =IF(predicciones_pcsaft!D33="","",predicciones_pcsaft!D33*7/Componentes!P10) | K37: =IF(OR(G37="",H37=""),"",H37-G37) | L37: =IF(OR(H37="",I37=""),"",I37-H37) | M37: =IF(OR(I37="",J37=""),"",J37-I37) | N37: =IF(OR(G37="",J37=""),"",J37-G37) | O37: =IF(N37="","",K37/N37) | P37: =IF(N37="","",L37/N37) | Q37: =IF(N37="","",M37/N37)
A38: 25 | C38: 5 | D38: =IF(predicciones_pcsaft!E34="","",predicciones_pcsaft!E34*7/$B$5) | E38: =IF(predicciones_pcsaft!C34="","",predicciones_pcsaft!C34*7/$B$4) | F38: =IF(predicciones_pcsaft!D34="","",predicciones_pcsaft!D34*7/Componentes!P10) | K38: =IF(OR(G38="",H38=""),"",H38-G38) | L38: =IF(OR(H38="",I38=""),"",I38-H38) | M38: =IF(OR(I38="",J38=""),"",J38-I38) | N38: =IF(OR(G38="",J38=""),"",J38-G38) | O38: =IF(N38="","",K38/N38) | P38: =IF(N38="","",L38/N38) | Q38: =IF(N38="","",M38/N38)
A40: 26 | B40: 2octanone | C40: 1 | D40: =IF(predicciones_pcsaft!E36="","",predicciones_pcsaft!E36*7/$B$5) | E40: =IF(predicciones_pcsaft!C36="","",predicciones_pcsaft!C36*7/$B$4) | F40: =IF(predicciones_pcsaft!D36="","",predicciones_pcsaft!D36*7/Componentes!P11) | K40: =IF(OR(G40="",H40=""),"",H40-G40) | L40: =IF(OR(H40="",I40=""),"",I40-H40) | M40: =IF(OR(I40="",J40=""),"",J40-I40) | N40: =IF(OR(G40="",J40=""),"",J40-G40) | O40: =IF(N40="","",K40/N40) | P40: =IF(N40="","",L40/N40) | Q40: =IF(N40="","",M40/N40)
A41: 27 | C41: 2 | D41: =IF(predicciones_pcsaft!E37="","",predicciones_pcsaft!E37*7/$B$5) | E41: =IF(predicciones_pcsaft!C37="","",predicciones_pcsaft!C37*7/$B$4) | F41: =IF(predicciones_pcsaft!D37="","",predicciones_pcsaft!D37*7/Componentes!P11) | K41: =IF(OR(G41="",H41=""),"",H41-G41) | L41: =IF(OR(H41="",I41=""),"",I41-H41) | M41: =IF(OR(I41="",J41=""),"",J41-I41) | N41: =IF(OR(G41="",J41=""),"",J41-G41) | O41: =IF(N41="","",K41/N41) | P41: =IF(N41="","",L41/N41) | Q41: =IF(N41="","",M41/N41)
A42: 28 | C42: 3 | D42: =IF(predicciones_pcsaft!E38="","",predicciones_pcsaft!E38*7/$B$5) | E42: =IF(predicciones_pcsaft!C38="","",predicciones_pcsaft!C38*7/$B$4) | F42: =IF(predicciones_pcsaft!D38="","",predicciones_pcsaft!D38*7/Componentes!P11) | K42: =IF(OR(G42="",H42=""),"",H42-G42) | L42: =IF(OR(H42="",I42=""),"",I42-H42) | M42: =IF(OR(I42="",J42=""),"",J42-I42) | N42: =IF(OR(G42="",J42=""),"",J42-G42) | O42: =IF(N42="","",K42/N42) | P42: =IF(N42="","",L42/N42) | Q42: =IF(N42="","",M42/N42)
A43: 29 | C43: 4 | D43: =IF(predicciones_pcsaft!E39="","",predicciones_pcsaft!E39*7/$B$5) | E43: =IF(predicciones_pcsaft!C39="","",predicciones_pcsaft!C39*7/$B$4) | F43: =IF(predicciones_pcsaft!D39="","",predicciones_pcsaft!D39*7/Componentes!P11) | K43: =IF(OR(G43="",H43=""),"",H43-G43) | L43: =IF(OR(H43="",I43=""),"",I43-H43) | M43: =IF(OR(I43="",J43=""),"",J43-I43) | N43: =IF(OR(G43="",J43=""),"",J43-G43) | O43: =IF(N43="","",K43/N43) | P43: =IF(N43="","",L43/N43) | Q43: =IF(N43="","",M43/N43)
A44: 30 | C44: 5 | D44: =IF(predicciones_pcsaft!E40="","",predicciones_pcsaft!E40*7/$B$5) | E44: =IF(predicciones_pcsaft!C40="","",predicciones_pcsaft!C40*7/$B$4) | F44: =IF(predicciones_pcsaft!D40="","",predicciones_pcsaft!D40*7/Componentes!P11) | K44: =IF(OR(G44="",H44=""),"",H44-G44) | L44: =IF(OR(H44="",I44=""),"",I44-H44) | M44: =IF(OR(I44="",J44=""),"",J44-I44) | N44: =IF(OR(G44="",J44=""),"",J44-G44) | O44: =IF(N44="","",K44/N44) | P44: =IF(N44="","",L44/N44) | Q44: =IF(N44="","",M44/N44)

Sheet Lab_DES
A1: LAB SHEET — 2-phenylethanol + DES + Water
A2: Add in order: tube → water → aroma → DES. Record cumulative balance reading after each addition.
A4: ρ_aroma (g/mL): | B4: =Componentes!P4 | C4: 2-phenylethanol
A5: ρ_water (g/mL): | B5: 0.997
B7: Pipetting guide (from predictions) | F7: Record on balance | J7: Auto-calculated by difference
A9: # | B9: DES | C9: HBA | D9: HBD | E9: TL# | F9: ρ_DES est (g/mL) | G9: V_water est (mL) | H9: V_aroma est (mL) | I9: V_DES est (mL) | J9: W_tube (g) | K9: W +water (g) | L9: W +aroma (g) | M9: W +DES (g) | N9: m_water (g) | O9: m_aroma (g) | P9: m_DES (g) | Q9: m_total (g) | R9: w_water | S9: w_aroma | T9: w_DES | U9: Notes
A10: 1 | B10: ThyCar | C10: Thymol | D10: Carvone | E10: 1 | F10: =(Componentes!AB12/(Componentes!AB12+Componentes!AB13))*Componentes!P12+(Componentes!AB13/(Componentes!AB12+Componentes!AB13))*Componentes!P13 | G10: =IF('2-phenylethanol_DES'!I6="","",'2-phenylethanol_DES'!I6*7/$B$5) | H10: =IF('2-phenylethanol_DES'!G6="","",'2-phenylethanol_DES'!G6*7/$B$4) | I10: =IF('2-phenylethanol_DES'!H6="","",'2-phenylethanol_DES'!H6*7/F10) | N10: =IF(OR(J10="",K10=""),"",K10-J10) | O10: =IF(OR(K10="",L10=""),"",L10-K10) | P10: =IF(OR(L10="",M10=""),"",M10-L10) | Q10: =IF(OR(J10="",M10=""),"",M10-J10) | R10: =IF(Q10="","",N10/Q10) | S10: =IF(Q10="","",O10/Q10) | T10: =IF(Q10="","",P10/Q10)
A11: 2 | E11: 2 | F11: =(Componentes!AB12/(Componentes!AB12+Componentes!AB13))*Componentes!P12+(Componentes!AB13/(Componentes!AB12+Componentes!AB13))*Componentes!P13 | G11: =IF('2-phenylethanol_DES'!I7="","",'2-phenylethanol_DES'!I7*7/$B$5) | H11: =IF('2-phenylethanol_DES'!G7="","",'2-phenylethanol_DES'!G7*7/$B$4) | I11: =IF('2-phenylethanol_DES'!H7="","",'2-phenylethanol_DES'!H7*7/F11) | N11: =IF(OR(J11="",K11=""),"",K11-J11) | O11: =IF(OR(K11="",L11=""),"",L11-K11) | P11: =IF(OR(L11="",M11=""),"",M11-L11) | Q11: =IF(OR(J11="",M11=""),"",M11-J11) | R11: =IF(Q11="","",N11/Q11) | S11: =IF(Q11="","",O11/Q11) | T11: =IF(Q11="","",P11/Q11)
A12: 3 | E12: 3 | F12: =(Componentes!AB12/(Componentes!AB12+Componentes!AB13))*Componentes!P12+(Componentes!AB13/(Componentes!AB12+Componentes!AB13))*Componentes!P13 | G12: =IF('2-phenylethanol_DES'!I8="","",'2-phenylethanol_DES'!I8*7/$B$5) | H12: =IF('2-phenylethanol_DES'!G8="","",'2-phenylethanol_DES'!G8*7/$B$4) | I12: =IF('2-phenylethanol_DES'!H8="","",'2-phenylethanol_DES'!H8*7/F12) | N12: =IF(OR(J12="",K12=""),"",K12-J12) | O12: =IF(OR(K12="",L12=""),"",L12-K12) | P12: =IF(OR(L12="",M12=""),"",M12-L12) | Q12: =IF(OR(J12="",M12=""),"",M12-J12) | R12: =IF(Q12="","",N12/Q12) | S12: =IF(Q12="","",O12/Q12) | T12: =IF(Q12="","",P12/Q12)
A13: 4 | E13: 4 | F13: =(Componentes!AB12/(Componentes!AB12+Componentes!AB13))*Componentes!P12+(Componentes!AB13/(Componentes!AB12+Componentes!AB13))*Componentes!P13 | G13: =IF('2-phenylethanol_DES'!I9="","",'2-phenylethanol_DES'!I9*7/$B$5) | H13: =IF('2-phenylethanol_DES'!G9="","",'2-phenylethanol_DES'!G9*7/$B$4) | I13: =IF('2-phenylethanol_DES'!H9="","",'2-phenylethanol_DES'!H9*7/F13) | N13: =IF(OR(J13="",K13=""),"",K13-J13) | O13: =IF(OR(K13="",L13=""),"",L13-K13) | P13: =IF(OR(L13="",M13=""),"",M13-L13) | Q13: =IF(OR(J13="",M13=""),"",M13-J13) | R13: =IF(Q13="","",N13/Q13) | S13: =IF(Q13="","",O13/Q13) | T13: =IF(Q13="","",P13/Q13)
A14: 5 | E14: 5 | F14: =(Componentes!AB12/(Componentes!AB12+Componentes!AB13))*Componentes!P12+(Componentes!AB13/(Componentes!AB12+Componentes!AB13))*Componentes!P13 | G14: =IF('2-phenylethanol_DES'!I10="","",'2-phenylethanol_DES'!I10*7/$B$5) | H14: =IF('2-phenylethanol_DES'!G10="","",'2-phenylethanol_DES'!G10*7/$B$4) | I14: =IF('2-phenylethanol_DES'!H10="","",'2-phenylethanol_DES'!H10*7/F14) | N14: =IF(OR(J14="",K14=""),"",K14-J14) | O14: =IF(OR(K14="",L14=""),"",L14-K14) | P14: =IF(OR(L14="",M14=""),"",M14-L14) | Q14: =IF(OR(J14="",M14=""),"",M14-J14) | R14: =IF(Q14="","",N14/Q14) | S14: =IF(Q14="","",O14/Q14) | T14: =IF(Q14="","",P14/Q14)
A16: 6 | B16: ThyGer | C16: Thymol | D16: Geraniol | E16: 1 | F16: =(Componentes!AB12/(Componentes!AB12+Componentes!AB15))*Componentes!P12+(Componentes!AB15/(Componentes!AB12+Componentes!AB15))*Componentes!P15 | G16: =IF('2-phenylethanol_DES'!I12="","",'2-phenylethanol_DES'!I12*7/$B$5) | H16: =IF('2-phenylethanol_DES'!G12="","",'2-phenylethanol_DES'!G12*7/$B$4) | I16: =IF('2-phenylethanol_DES'!H12="","",'2-phenylethanol_DES'!H12*7/F16) | N16: =IF(OR(J16="",K16=""),"",K16-J16) | O16: =IF(OR(K16="",L16=""),"",L16-K16) | P16: =IF(OR(L16="",M16=""),"",M16-L16) | Q16: =IF(OR(J16="",M16=""),"",M16-J16) | R16: =IF(Q16="","",N16/Q16) | S16: =IF(Q16="","",O16/Q16) | T16: =IF(Q16="","",P16/Q16)
A17: 7 | E17: 2 | F17: =(Componentes!AB12/(Componentes!AB12+Componentes!AB15))*Componentes!P12+(Componentes!AB15/(Componentes!AB12+Componentes!AB15))*Componentes!P15 | G17: =IF('2-phenylethanol_DES'!I13="","",'2-phenylethanol_DES'!I13*7/$B$5) | H17: =IF('2-phenylethanol_DES'!G13="","",'2-phenylethanol_DES'!G13*7/$B$4) | I17: =IF('2-phenylethanol_DES'!H13="","",'2-phenylethanol_DES'!H13*7/F17) | N17: =IF(OR(J17="",K17=""),"",K17-J17) | O17: =IF(OR(K17="",L17=""),"",L17-K17) | P17: =IF(OR(L17="",M17=""),"",M17-L17) | Q17: =IF(OR(J17="",M17=""),"",M17-J17) | R17: =IF(Q17="","",N17/Q17) | S17: =IF(Q17="","",O17/Q17) | T17: =IF(Q17="","",P17/Q17)
A18: 8 | E18: 3 | F18: =(Componentes!AB12/(Componentes!AB12+Componentes!AB15))*Componentes!P12+(Componentes!AB15/(Componentes!AB12+Componentes!AB15))*Componentes!P15 | G18: =IF('2-phenylethanol_DES'!I14="","",'2-phenylethanol_DES'!I14*7/$B$5) | H18: =IF('2-phenylethanol_DES'!G14="","",'2-phenylethanol_DES'!G14*7/$B$4) | I18: =IF('2-phenylethanol_DES'!H14="","",'2-phenylethanol_DES'!H14*7/F18) | N18: =IF(OR(J18="",K18=""),"",K18-J18) | O18: =IF(OR(K18="",L18=""),"",L18-K18) | P18: =IF(OR(L18="",M18=""),"",M18-L18) | Q18: =IF(OR(J18="",M18=""),"",M18-J18) | R18: =IF(Q18="","",N18/Q18) | S18: =IF(Q18="","",O18/Q18) | T18: =IF(Q18="","",P18/Q18)
A19: 9 | E19: 4 | F19: =(Componentes!AB12/(Componentes!AB12+Componentes!AB15))*Componentes!P12+(Componentes!AB15/(Componentes!AB12+Componentes!AB15))*Componentes!P15 | G19: =IF('2-phenylethanol_DES'!I15="","",'2-phenylethanol_DES'!I15*7/$B$5) | H19: =IF('2-phenylethanol_DES'!G15="","",'2-phenylethanol_DES'!G15*7/$B$4) | I19: =IF('2-phenylethanol_DES'!H15="","",'2-phenylethanol_DES'!H15*7/F19) | N19: =IF(OR(J19="",K19=""),"",K19-J19) | O19: =IF(OR(K19="",L19=""),"",L19-K19) | P19: =IF(OR(L19="",M19=""),"",M19-L19) | Q19: =IF(OR(J19="",M19=""),"",M19-J19) | R19: =IF(Q19="","",N19/Q19) | S19: =IF(Q19="","",O19/Q19) | T19: =IF(Q19="","",P19/Q19)
A20: 10 | E20: 5 | F20: =(Componentes!AB12/(Componentes!AB12+Componentes!AB15))*Componentes!P12+(Componentes!AB15/(Componentes!AB12+Componentes!AB15))*Componentes!P15 | G20: =IF('2-phenylethanol_DES'!I16="","",'2-phenylethanol_DES'!I16*7/$B$5) | H20: =IF('2-phenylethanol_DES'!G16="","",'2-phenylethanol_DES'!G16*7/$B$4) | I20: =IF('2-phenylethanol_DES'!H16="","",'2-phenylethanol_DES'!H16*7/F20) | N20: =IF(OR(J20="",K20=""),"",K20-J20) | O20: =IF(OR(K20="",L20=""),"",L20-K20) | P20: =IF(OR(L20="",M20=""),"",M20-L20) | Q20: =IF(OR(J20="",M20=""),"",M20-J20) | R20: =IF(Q20="","",N20/Q20) | S20: =IF(Q20="","",O20/Q20) | T20: =IF(Q20="","",P20/Q20)
A22: 11 | B22: ThyCarvac | C22: Thymol | D22: Carvacrol | E22: 1 | F22: =(Componentes!AB12/(Componentes!AB12+Componentes!AB16))*Componentes!P12+(Componentes!AB16/(Componentes!AB12+Componentes!AB16))*Componentes!P16 | G22: =IF('2-phenylethanol_DES'!I18="","",'2-phenylethanol_DES'!I18*7/$B$5) | H22: =IF('2-phenylethanol_DES'!G18="","",'2-phenylethanol_DES'!G18*7/$B$4) | I22: =IF('2-phenylethanol_DES'!H18="","",'2-phenylethanol_DES'!H18*7/F22) | N22: =IF(OR(J22="",K22=""),"",K22-J22) | O22: =IF(OR(K22="",L22=""),"",L22-K22) | P22: =IF(OR(L22="",M22=""),"",M22-L22) | Q22: =IF(OR(J22="",M22=""),"",M22-J22) | R22: =IF(Q22="","",N22/Q22) | S22: =IF(Q22="","",O22/Q22) | T22: =IF(Q22="","",P22/Q22)
A23: 12 | E23: 2 | F23: =(Componentes!AB12/(Componentes!AB12+Componentes!AB16))*Componentes!P12+(Componentes!AB16/(Componentes!AB12+Componentes!AB16))*Componentes!P16 | G23: =IF('2-phenylethanol_DES'!I19="","",'2-phenylethanol_DES'!I19*7/$B$5) | H23: =IF('2-phenylethanol_DES'!G19="","",'2-phenylethanol_DES'!G19*7/$B$4) | I23: =IF('2-phenylethanol_DES'!H19="","",'2-phenylethanol_DES'!H19*7/F23) | N23: =IF(OR(J23="",K23=""),"",K23-J23) | O23: =IF(OR(K23="",L23=""),"",L23-K23) | P23: =IF(OR(L23="",M23=""),"",M23-L23) | Q23: =IF(OR(J23="",M23=""),"",M23-J23) | R23: =IF(Q23="","",N23/Q23) | S23: =IF(Q23="","",O23/Q23) | T23: =IF(Q23="","",P23/Q23)
A24: 13 | E24: 3 | F24: =(Componentes!AB12/(Componentes!AB12+Componentes!AB16))*Componentes!P12+(Componentes!AB16/(Componentes!AB12+Componentes!AB16))*Componentes!P16 | G24: =IF('2-phenylethanol_DES'!I20="","",'2-phenylethanol_DES'!I20*7/$B$5) | H24: =IF('2-phenylethanol_DES'!G20="","",'2-phenylethanol_DES'!G20*7/$B$4) | I24: =IF('2-phenylethanol_DES'!H20="","",'2-phenylethanol_DES'!H20*7/F24) | N24: =IF(OR(J24="",K24=""),"",K24-J24) | O24: =IF(OR(K24="",L24=""),"",L24-K24) | P24: =IF(OR(L24="",M24=""),"",M24-L24) | Q24: =IF(OR(J24="",M24=""),"",M24-J24) | R24: =IF(Q24="","",N24/Q24) | S24: =IF(Q24="","",O24/Q24) | T24: =IF(Q24="","",P24/Q24)
A25: 14 | E25: 4 | F25: =(Componentes!AB12/(Componentes!AB12+Componentes!AB16))*Componentes!P12+(Componentes!AB16/(Componentes!AB12+Componentes!AB16))*Componentes!P16 | G25: =IF('2-phenylethanol_DES'!I21="","",'2-phenylethanol_DES'!I21*7/$B$5) | H25: =IF('2-phenylethanol_DES'!G21="","",'2-phenylethanol_DES'!G21*7/$B$4) | I25: =IF('2-phenylethanol_DES'!H21="","",'2-phenylethanol_DES'!H21*7/F25) | N25: =IF(OR(J25="",K25=""),"",K25-J25) | O25: =IF(OR(K25="",L25=""),"",L25-K25) | P25: =IF(OR(L25="",M25=""),"",M25-L25) | Q25: =IF(OR(J25="",M25=""),"",M25-J25) | R25: =IF(Q25="","",N25/Q25) | S25: =IF(Q25="","",O25/Q25) | T25: =IF(Q25="","",P25/Q25)
A26: 15 | E26: 5 | F26: =(Componentes!AB12/(Componentes!AB12+Componentes!AB16))*Componentes!P12+(Componentes!AB16/(Componentes!AB12+Componentes!AB16))*Componentes!P16 | G26: =IF('2-phenylethanol_DES'!I22="","",'2-phenylethanol_DES'!I22*7/$B$5) | H26: =IF('2-phenylethanol_DES'!G22="","",'2-phenylethanol_DES'!G22*7/$B$4) | I26: =IF('2-phenylethanol_DES'!H22="","",'2-phenylethanol_DES'!H22*7/F26) | N26: =IF(OR(J26="",K26=""),"",K26-J26) | O26: =IF(OR(K26="",L26=""),"",L26-K26) | P26: =IF(OR(L26="",M26=""),"",M26-L26) | Q26: =IF(OR(J26="",M26=""),"",M26-J26) | R26: =IF(Q26="","",N26/Q26) | S26: =IF(Q26="","",O26/Q26) | T26: =IF(Q26="","",P26/Q26)
A28: 16 | B28: ThyEug | C28: Thymol | D28: Eugenol | E28: 1 | F28: =(Componentes!AB12/(Componentes!AB12+Componentes!AB17))*Componentes!P12+(Componentes!AB17/(Componentes!AB12+Componentes!AB17))*Componentes!P17 | G28: =IF('2-phenylethanol_DES'!I24="","",'2-phenylethanol_DES'!I24*7/$B$5) | H28: =IF('2-phenylethanol_DES'!G24="","",'2-phenylethanol_DES'!G24*7/$B$4) | I28: =IF('2-phenylethanol_DES'!H24="","",'2-phenylethanol_DES'!H24*7/F28) | N28: =IF(OR(J28="",K28=""),"",K28-J28) | O28: =IF(OR(K28="",L28=""),"",L28-K28) | P28: =IF(OR(L28="",M28=""),"",M28-L28) | Q28: =IF(OR(J28="",M28=""),"",M28-J28) | R28: =IF(Q28="","",N28/Q28) | S28: =IF(Q28="","",O28/Q28) | T28: =IF(Q28="","",P28/Q28)
A29: 17 | E29: 2 | F29: =(Componentes!AB12/(Componentes!AB12+Componentes!AB17))*Componentes!P12+(Componentes!AB17/(Componentes!AB12+Componentes!AB17))*Componentes!P17 | G29: =IF('2-phenylethanol_DES'!I25="","",'2-phenylethanol_DES'!I25*7/$B$5) | H29: =IF('2-phenylethanol_DES'!G25="","",'2-phenylethanol_DES'!G25*7/$B$4) | I29: =IF('2-phenylethanol_DES'!H25="","",'2-phenylethanol_DES'!H25*7/F29) | N29: =IF(OR(J29="",K29=""),"",K29-J29) | O29: =IF(OR(K29="",L29=""),"",L29-K29) | P29: =IF(OR(L29="",M29=""),"",M29-L29) | Q29: =IF(OR(J29="",M29=""),"",M29-J29) | R29: =IF(Q29="","",N29/Q29) | S29: =IF(Q29="","",O29/Q29) | T29: =IF(Q29="","",P29/Q29)
A30: 18 | E30: 3 | F30: =(Componentes!AB12/(Componentes!AB12+Componentes!AB17))*Componentes!P12+(Componentes!AB17/(Componentes!AB12+Componentes!AB17))*Componentes!P17 | G30: =IF('2-phenylethanol_DES'!I26="","",'2-phenylethanol_DES'!I26*7/$B$5) | H30: =IF('2-phenylethanol_DES'!G26="","",'2-phenylethanol_DES'!G26*7/$B$4) | I30: =IF('2-phenylethanol_DES'!H26="","",'2-phenylethanol_DES'!H26*7/F30) | N30: =IF(OR(J30="",K30=""),"",K30-J30) | O30: =IF(OR(K30="",L30=""),"",L30-K30) | P30: =IF(OR(L30="",M30=""),"",M30-L30) | Q30: =IF(OR(J30="",M30=""),"",M30-J30) | R30: =IF(Q30="","",N30/Q30) | S30: =IF(Q30="","",O30/Q30) | T30: =IF(Q30="","",P30/Q30)
A31: 19 | E31: 4 | F31: =(Componentes!AB12/(Componentes!AB12+Componentes!AB17))*Componentes!P12+(Componentes!AB17/(Componentes!AB12+Componentes!AB17))*Componentes!P17 | G31: =IF('2-phenylethanol_DES'!I27="","",'2-phenylethanol_DES'!I27*7/$B$5) | H31: =IF('2-phenylethanol_DES'!G27="","",'2-phenylethanol_DES'!G27*7/$B$4) | I31: =IF('2-phenylethanol_DES'!H27="","",'2-phenylethanol_DES'!H27*7/F31) | N31: =IF(OR(J31="",K31=""),"",K31-J31) | O31: =IF(OR(K31="",L31=""),"",L31-K31) | P31: =IF(OR(L31="",M31=""),"",M31-L31) | Q31: =IF(OR(J31="",M31=""),"",M31-J31) | R31: =IF(Q31="","",N31/Q31) | S31: =IF(Q31="","",O31/Q31) | T31: =IF(Q31="","",P31/Q31)
A32: 20 | E32: 5 | F32: =(Componentes!AB12/(Componentes!AB12+Componentes!AB17))*Componentes!P12+(Componentes!AB17/(Componentes!AB12+Componentes!AB17))*Componentes!P17 | G32: =IF('2-phenylethanol_DES'!I28="","",'2-phenylethanol_DES'!I28*7/$B$5) | H32: =IF('2-phenylethanol_DES'!G28="","",'2-phenylethanol_DES'!G28*7/$B$4) | I32: =IF('2-phenylethanol_DES'!H28="","",'2-phenylethanol_DES'!H28*7/F32) | N32: =IF(OR(J32="",K32=""),"",K32-J32) | O32: =IF(OR(K32="",L32=""),"",L32-K32) | P32: =IF(OR(L32="",M32=""),"",M32-L32) | Q32: =IF(OR(J32="",M32=""),"",M32-J32) | R32: =IF(Q32="","",N32/Q32) | S32: =IF(Q32="","",O32/Q32) | T32: =IF(Q32="","",P32/Q32)
A34: 21 | B34: ThyCam | C34: Thymol | D34: Camphor | E34: 1 | F34: =(Componentes!AB12/(Componentes!AB12+Componentes!AB14))*Componentes!P12+(Componentes!AB14/(Componentes!AB12+Componentes!AB14))*Componentes!P14 | G34: =IF('2-phenylethanol_DES'!I30="","",'2-phenylethanol_DES'!I30*7/$B$5) | H34: =IF('2-phenylethanol_DES'!G30="","",'2-phenylethanol_DES'!G30*7/$B$4) | I34: =IF('2-phenylethanol_DES'!H30="","",'2-phenylethanol_DES'!H30*7/F34) | N34: =IF(OR(J34="",K34=""),"",K34-J34) | O34: =IF(OR(K34="",L34=""),"",L34-K34) | P34: =IF(OR(L34="",M34=""),"",M34-L34) | Q34: =IF(OR(J34="",M34=""),"",M34-J34) | R34: =IF(Q34="","",N34/Q34) | S34: =IF(Q34="","",O34/Q34) | T34: =IF(Q34="","",P34/Q34)
A35: 22 | E35: 2 | F35: =(Componentes!AB12/(Componentes!AB12+Componentes!AB14))*Componentes!P12+(Componentes!AB14/(Componentes!AB12+Componentes!AB14))*Componentes!P14 | G35: =IF('2-phenylethanol_DES'!I31="","",'2-phenylethanol_DES'!I31*7/$B$5) | H35: =IF('2-phenylethanol_DES'!G31="","",'2-phenylethanol_DES'!G31*7/$B$4) | I35: =IF('2-phenylethanol_DES'!H31="","",'2-phenylethanol_DES'!H31*7/F35) | N35: =IF(OR(J35="",K35=""),"",K35-J35) | O35: =IF(OR(K35="",L35=""),"",L35-K35) | P35: =IF(OR(L35="",M35=""),"",M35-L35) | Q35: =IF(OR(J35="",M35=""),"",M35-J35) | R35: =IF(Q35="","",N35/Q35) | S35: =IF(Q35="","",O35/Q35) | T35: =IF(Q35="","",P35/Q35)
A36: 23 | E36: 3 | F36: =(Componentes!AB12/(Componentes!AB12+Componentes!AB14))*Componentes!P12+(Componentes!AB14/(Componentes!AB12+Componentes!AB14))*Componentes!P14 | G36: =IF('2-phenylethanol_DES'!I32="","",'2-phenylethanol_DES'!I32*7/$B$5) | H36: =IF('2-phenylethanol_DES'!G32="","",'2-phenylethanol_DES'!G32*7/$B$4) | I36: =IF('2-phenylethanol_DES'!H32="","",'2-phenylethanol_DES'!H32*7/F36) | N36: =IF(OR(J36="",K36=""),"",K36-J36) | O36: =IF(OR(K36="",L36=""),"",L36-K36) | P36: =IF(OR(L36="",M36=""),"",M36-L36) | Q36: =IF(OR(J36="",M36=""),"",M36-J36) | R36: =IF(Q36="","",N36/Q36) | S36: =IF(Q36="","",O36/Q36) | T36: =IF(Q36="","",P36/Q36)
A37: 24 | E37: 4 | F37: =(Componentes!AB12/(Componentes!AB12+Componentes!AB14))*Componentes!P12+(Componentes!AB14/(Componentes!AB12+Componentes!AB14))*Componentes!P14 | G37: =IF('2-phenylethanol_DES'!I33="","",'2-phenylethanol_DES'!I33*7/$B$5) | H37: =IF('2-phenylethanol_DES'!G33="","",'2-phenylethanol_DES'!G33*7/$B$4) | I37: =IF('2-phenylethanol_DES'!H33="","",'2-phenylethanol_DES'!H33*7/F37) | N37: =IF(OR(J37="",K37=""),"",K37-J37) | O37: =IF(OR(K37="",L37=""),"",L37-K37) | P37: =IF(OR(L37="",M37=""),"",M37-L37) | Q37: =IF(OR(J37="",M37=""),"",M37-J37) | R37: =IF(Q37="","",N37/Q37) | S37: =IF(Q37="","",O37/Q37) | T37: =IF(Q37="","",P37/Q37)
A38: 25 | E38: 5 | F38: =(Componentes!AB12/(Componentes!AB12+Componentes!AB14))*Componentes!P12+(Componentes!AB14/(Componentes!AB12+Componentes!AB14))*Componentes!P14 | G38: =IF('2-phenylethanol_DES'!I34="","",'2-phenylethanol_DES'!I34*7/$B$5) | H38: =IF('2-phenylethanol_DES'!G34="","",'2-phenylethanol_DES'!G34*7/$B$4) | I38: =IF('2-phenylethanol_DES'!H34="","",'2-phenylethanol_DES'!H34*7/F38) | N38: =IF(OR(J38="",K38=""),"",K38-J38) | O38: =IF(OR(K38="",L38=""),"",L38-K38) | P38: =IF(OR(L38="",M38=""),"",M38-L38) | Q38: =IF(OR(J38="",M38=""),"",M38-J38) | R38: =IF(Q38="","",N38/Q38) | S38: =IF(Q38="","",O38/Q38) | T38: =IF(Q38="","",P38/Q38)
A40: 26 | B40: CamCar | C40: Camphor | D40: Carvone | E40: 1 | F40: =(Componentes!AB14/(Componentes!AB14+Componentes!AB13))*Componentes!P14+(Componentes!AB13/(Componentes!AB14+Componentes!AB13))*Componentes!P13 | G40: =IF('2-phenylethanol_DES'!I36="","",'2-phenylethanol_DES'!I36*7/$B$5) | H40: =IF('2-phenylethanol_DES'!G36="","",'2-phenylethanol_DES'!G36*7/$B$4) | I40: =IF('2-phenylethanol_DES'!H36="","",'2-phenylethanol_DES'!H36*7/F40) | N40: =IF(OR(J40="",K40=""),"",K40-J40) | O40: =IF(OR(K40="",L40=""),"",L40-K40) | P40: =IF(OR(L40="",M40=""),"",M40-L40) | Q40: =IF(OR(J40="",M40=""),"",M40-J40) | R40: =IF(Q40="","",N40/Q40) | S40: =IF(Q40="","",O40/Q40) | T40: =IF(Q40="","",P40/Q40)
A41: 27 | E41: 2 | F41: =(Componentes!AB14/(Componentes!AB14+Componentes!AB13))*Componentes!P14+(Componentes!AB13/(Componentes!AB14+Componentes!AB13))*Componentes!P13 | G41: =IF('2-phenylethanol_DES'!I37="","",'2-phenylethanol_DES'!I37*7/$B$5) | H41: =IF('2-phenylethanol_DES'!G37="","",'2-phenylethanol_DES'!G37*7/$B$4) | I41: =IF('2-phenylethanol_DES'!H37="","",'2-phenylethanol_DES'!H37*7/F41) | N41: =IF(OR(J41="",K41=""),"",K41-J41) | O41: =IF(OR(K41="",L41=""),"",L41-K41) | P41: =IF(OR(L41="",M41=""),"",M41-L41) | Q41: =IF(OR(J41="",M41=""),"",M41-J41) | R41: =IF(Q41="","",N41/Q41) | S41: =IF(Q41="","",O41/Q41) | T41: =IF(Q41="","",P41/Q41)
