Workbook

Sheet predicciones_pcsaft
A1: Target mass (g): | B1: 7 | C1: ← change here to rescale all masses
A2: Aroma: β-ionone (trans)
A3: Yellow = paste z (mass fracs) from software | Green = auto-calculated masses
A5: Solvent | B5: TL# | C5: z_aroma | D5: z_solvent | E5: z_water | F5: Σz (check) | G5: m_aroma (g) | H5: m_solvent (g) | I5: m_water (g) | J5: m_total (g)
A18: hexoh | B18: 1 | C18: 0.475 | D18: 0.0201 | E18: 0.5049 | F18: =IF(C18="","",C18+D18+E18) -> 1 | G18: =IF(C18="","",C18*$B$1) -> 3.325 | H18: =IF(D18="","",D18*$B$1) -> 0.1407 | I18: =IF(E18="","",E18*$B$1) -> 3.5343 | J18: =IF(G18="","",G18+H18+I18) -> 7
B19: 2 | C19: 0.0202 | D19: 0.43 | E19: 0.5498 | F19: =IF(C19="","",C19+D19+E19) -> 1 | G19: =IF(C19="","",C19*$B$1) -> 0.1414 | H19: =IF(D19="","",D19*$B$1) -> 3.01 | I19: =IF(E19="","",E19*$B$1) -> 3.8486 | J19: =IF(G19="","",G19+H19+I19) -> 7
B20: 3 | C20: 0.2646 | D20: 0.2114 | E20: 0.524 | F20: =IF(C20="","",C20+D20+E20) -> 1 | G20: =IF(C20="","",C20*$B$1) -> 1.8522 | H20: =IF(D20="","",D20*$B$1) -> 1.4798 | I20: =IF(E20="","",E20*$B$1) -> 3.668 | J20: =IF(G20="","",G20+H20+I20) -> 7
B21: 4 | C21: 0.3734 | D21: 0.1128 | E21: 0.5138 | F21: =IF(C21="","",C21+D21+E21) -> 1 | G21: =IF(C21="","",C21*$B$1) -> 2.6138 | H21: =IF(D21="","",D21*$B$1) -> 0.7896 | I21: =IF(E21="","",E21*$B$1) -> 3.5966 | J21: =IF(G21="","",G21+H21+I21) -> 7
B22: 5 | C22: 0.1484 | D22: 0.3159 | E22: 0.5357 | F22: =IF(C22="","",C22+D22+E22) -> 1 | G22: =IF(C22="","",C22*$B$1) -> 1.0388 | H22: =IF(D22="","",D22*$B$1) -> 2.2113 | I22: =IF(E22="","",E22*$B$1) -> 3.7499 | J22: =IF(G22="","",G22+H22+I22) -> 7
B24: 1 | F24: =IF(C24="","",C24+D24+E24) | G24: =IF(C24="","",C24*$B$1) | H24: =IF(D24="","",D24*$B$1) | I24: =IF(E24="","",E24*$B$1) | J24: =IF(G24="","",G24+H24+I24)
B25: 2 | F25: =IF(C25="","",C25+D25+E25) | G25: =IF(C25="","",C25*$B$1) | H25: =IF(D25="","",D25*$B$1) | I25: =IF(E25="","",E25*$B$1) | J25: =IF(G25="","",G25+H25+I25)
B26: 3 | F26: =IF(C26="","",C26+D26+E26) | G26: =IF(C26="","",C26*$B$1) | H26: =IF(D26="","",D26*$B$1) | I26: =IF(E26="","",E26*$B$1) | J26: =IF(G26="","",G26+H26+I26)
B27: 4 | F27: =IF(C27="","",C27+D27+E27) | G27: =IF(C27="","",C27*$B$1) | H27: =IF(D27="","",D27*$B$1) | I27: =IF(E27="","",E27*$B$1) | J27: =IF(G27="","",G27+H27+I27)
B28: 5 | F28: =IF(C28="","",C28+D28+E28) | G28: =IF(C28="","",C28*$B$1) | H28: =IF(D28="","",D28*$B$1) | I28: =IF(E28="","",E28*$B$1) | J28: =IF(G28="","",G28+H28+I28)
A30: mibk | B30: 1 | C30: 0.0204 | D30: 0.4357 | E30: 0.5439 | F30: =IF(C30="","",C30+D30+E30) -> 1 | G30: =IF(C30="","",C30*$B$1) -> 0.1428 | H30: =IF(D30="","",D30*$B$1) -> 3.0499 | I30: =IF(E30="","",E30*$B$1) -> 3.8073 | J30: =IF(G30="","",G30+H30+I30) -> 7
B31: 2 | C31: 0.4748 | D31: 0.0201 | E31: 0.5051 | F31: =IF(C31="","",C31+D31+E31) -> 1 | G31: =IF(C31="","",C31*$B$1) -> 3.3236 | H31: =IF(D31="","",D31*$B$1) -> 0.1407 | I31: =IF(E31="","",E31*$B$1) -> 3.5357 | J31: =IF(G31="","",G31+H31+I31) -> 7
B32: 3 | C32: 0.2605 | D32: 0.2155 | E32: 0.5239 | F32: =IF(C32="","",C32+D32+E32) -> 0.9999 | G32: =IF(C32="","",C32*$B$1) -> 1.8235 | H32: =IF(D32="","",D32*$B$1) -> 1.5085 | I32: =IF(E32="","",E32*$B$1) -> 3.6673 | J32: =IF(G32="","",G32+H32+I32) -> 6.9993
B33: 4 | C33: 0.1443 | D33: 0.322 | E33: 0.5337 | F33: =IF(C33="","",C33+D33+E33) -> 1 | G33: =IF(C33="","",C33*$B$1) -> 1.0101 | H33: =IF(D33="","",D33*$B$1) -> 2.254 | I33: =IF(E33="","",E33*$B$1) -> 3.7359 | J33: =IF(G33="","",G33+H33+I33) -> 7
B34: 5 | C34: 0.3711 | D34: 0.1145 | E34: 0.5144 | F34: =IF(C34="","",C34+D34+E34) -> 1 | G34: =IF(C34="","",C34*$B$1) -> 2.5977 | H34: =IF(D34="","",D34*$B$1) -> 0.8015 | I34: =IF(E34="","",E34*$B$1) -> 3.6008 | J34: =IF(G34="","",G34+H34+I34) -> 7
A36: 2octanone | B36: 1 | C36: 0.0201 | D36: 0.4415 | E36: 0.5384 | F36: =IF(C36="","",C36+D36+E36) -> 1 | G36: =IF(C36="","",C36*$B$1) -> 0.1407 | H36: =IF(D36="","",D36*$B$1) -> 3.0905 | I36: =IF(E36="","",E36*$B$1) -> 3.7688 | J36: =IF(G36="","",G36+H36+I36) -> 7
B37: 2 | C37: 0.4748 | D37: 0.0204 | E37: 0.5048 | F37: =IF(C37="","",C37+D37+E37) -> 1 | G37: =IF(C37="","",C37*$B$1) -> 3.3236 | H37: =IF(D37="","",D37*$B$1) -> 0.1428 | I37: =IF(E37="","",E37*$B$1) -> 3.5336 | J37: =IF(G37="","",G37+H37+I37) -> 7
B38: 3 | C38: 0.2571 | D38: 0.2218 | E38: 0.521 | F38: =IF(C38="","",C38+D38+E38) -> 0.9999 | G38: =IF(C38="","",C38*$B$1) -> 1.7997 | H38: =IF(D38="","",D38*$B$1) -> 1.5526 | I38: =IF(E38="","",E38*$B$1) -> 3.647 | J38: =IF(G38="","",G38+H38+I38) -> 6.9993
B39: 4 | C39: 0.3682 | D39: 0.119 | E39: 0.5128 | F39: =IF(C39="","",C39+D39+E39) -> 1 | G39: =IF(C39="","",C39*$B$1) -> 2.5774 | H39: =IF(D39="","",D39*$B$1) -> 0.833 | I39: =IF(E39="","",E39*$B$1) -> 3.5896 | J39: =IF(G39="","",G39+H39+I39) -> 7
B40: 5 | C40: 0.1411 | D40: 0.3293 | E40: 0.5296 | F40: =IF(C40="","",C40+D40+E40) -> 1 | G40: =IF(C40="","",C40*$B$1) -> 0.9877 | H40: =IF(D40="","",D40*$B$1) -> 2.3051 | I40: =IF(E40="","",E40*$B$1) -> 3.7072 | J40: =IF(G40="","",G40+H40+I40) -> 7

Sheet Componentes
A1: IDENTIFICADOR | G1: INVENTARIO | M1: PROPIEDADES | S1: SEGURIDAD | V1: METADATA
A2: ID | B2: Chemical Name | C2: Common Name(s) | D2: CAS Number | E2: Formula | F2: Canonical SMILES | G2: Location | H2: Supplier | I2: Grade/Purity | J2: Lot Number | K2: Quantity | L2: Unit | M2: MW | N2: Tb | O2: Tm | P2: ρ (25°C) | Q2: η (25°C) | R2: Pᵛᵃᵖ (25°C) | S2: Flash Point | T2: Hazard Class | U2: Storage | V2: Date Received | W2: Status | X2: Notes | AA2: comp_id | AB2: MW | AC2: purity
A3: Internal component code | B3: IUPAC or standard name | C3: Alternative names | D3: CAS registry number | E3: Molecular formula | F3: For modeling/databases | G3: Lab position (e.g., 3.1) | H3: Vendor name | I3: (Según batch) | J3: Batch identifier | K3: Amount available | L3: mL, g, kg, etc. | M3: g/mol | N3: °C (1 atm) | O3: °C | P3: g/cm³ | Q3: mPa·s | R3: kPa | S3: °C | T3: GHS classification | U3: Requirements | V3: YYYY-MM-DD | W3: Active/Depleted | X3: Additional info | AA3: beta | AB3: 192.3 | AC3: 0.978
A4: beta | B4: b-ionone (trans) | C4: - | D4: 14901-07-6 | E4: C13H20O | F4: CC1=C(C(CCC1)(C)C)/C=C/C(=O)C | G4: REFRIGERADOR | H4: Sigma-Aldrich | I4: 97.8% (GC) | J4: SHBL2869 | K4: 1 | L4: L | M4: 192.3 | N4: 266 | O4: - | P4: 0.94498 | R4: - | S4: - | T4: - | U4: - | V4: - | W4: Active | AA4: 2pe | AB4: 122.16 | AC4: 1
A5: 2pe | B5: 2-phenylethanol | C5: - | D5: 60-12-8 | E5: C8H10O | F5: OCCc1ccccc1 | G5: 3.x | H5: Sigma-Aldrich | I5: > 99.9% (GC) | J5: SDBB2371 | K5: 1 | L5: L | M5: 122.16 | N5: 219 | O5: - | P5: 1.01985 | R5: - | S5: - | T5: - | U5: - | V5: - | W5: Active | AA5: gamma | AB5: 170.25 | AC5: 0.987
A6: gamma | B6: g-decalactone | C6: - | D6: 706-14-9 | E6: C10H18O2 | F6: CCCCCCC1CCC(=O)O1 | G6: 3.x | H6: Sigma-Aldrich | I6: 98.7% (GC) | J6: SHBR4960 | K6: 1 | L6: L | M6: 170.25 | N6: 285 | O6: - | P6: 0.95292 | R6: - | S6: - | T6: - | U6: - | V6: - | W6: Active | AA6: 2m3b2oh | AB6: 86.13 | AC6: 0.996
A7: 2m3b2oh | B7: 2-methyl-3-buten-2-ol | C7: 2M3B2OH | D7: 115-18-4 | E7: C5H10O | F7: CC(C)(C=C)O | G7: REFRIGERADOR | H7: Aldrich | I7: 99.6% (GC) | J7: STBH5331 | K7: 1 | L7: L | M7: 86.13 | N7: 99 | O7: - | P7: 0.82388 | R7: - | S7: - | T7: - | U7: - | V7: - | W7: Active | AA7: 2m2boh | AB7: 88.15 | AC7: 1
A8: 2m2boh | B8: 2-methyl-2-butanol | C8: tert-amyl alcohol | D8: 75-85-4 | E8: C5H12O | F8: CCC(C)(C)O | G8: 3.2 | H8: Sigma-Aldrich | I8: >99.9% (GC) | J8: SDBB4598 | K8: 1 | L8: L | M8: 88.15 | N8: 102 | O8: - | P8: 0.80899 | R8: - | S8: - | T8: - | U8: - | V8: - | W8: Active | AA8: hexoh | AB8: 102.17 | AC8: 0.998
A9: hexoh | B9: 1-hexanol | C9: - | D9: 111-27-3 | E9: C6H18O | F9: CCCCCCO | G9: 1.3. | H9: Sigma-Aldrich | I9: 99.8% (GC) | J9: SHBC9189V | K9: 700 | L9: mL | M9: 102.17 | N9: 156 | O9: - | P9: 0.81883 | R9: - | S9: - | T9: - | U9: - | V9: - | W9: Active | AA9: octoh | AB9: 130.23 | AC9: 0.997
A10: octoh | B10: 1-octanol | C10: - | D10: 111-87-5 | E10: C8H18O | F10: CCCCCCCCO | G10: 1.2 | H10: Sigma-Aldrich | I10: 99.7% (GC) | J10: SDBB1117 | K10: 200? | L10: mL | M10: 130.23 | N10: 195 | O10: - | P10: 0.82518 | R10: - | S10: - | T10: - | U10: - | V10: - | W10: Active | AA10: mibk | AB10: 100.16 | AC10: 0.998
A11: mibk | B11: methyl isobutyl ketone | C11: MIBK | D11: 108-10-1 | E11: C6H12O | F11: CC(C)CC(=O)C | G11: 2.4 | H11: Merck Millipor | I11: 99.8% (GC) | J11: K51239346927 | K11: 300? | L11: mL | M11: 100.16 | N11: 115 | O11: - | P11: 0.80143 | R11: - | S11: - | T11: - | U11: - | V11: - | W11: Active | AA11: 2octanone | AB11: 128.21 | AC11: 0.988
A12: 2octanone | B12: 2-octanone | C12: Hexyl methyl ketone | D12: 111-13-7 | E12: C8H16O | F12: CCCCCCC(=O)C | G12: 3.2 | H12: Sigma-Aldrich | I12: 98.8% (GC) | J12: SHBQ4121 | K12: 200? | L12: mL | M12: 128.21 | N12: 173 | O12: - | P12: 0.81906 | R12: - | S12: - | T12: - | U12: - | V12: - | W12: Active | AA12: thymol | AB12: 150.22 | AC12: 0.999
A13: thymol | B13: Thymol | C13: - | D13: 89-83-8 | E13: C10H14O | F13: Cc1ccc(C(C)C)c(O)c1 | G13: 1.2 | H13: Sigma-Aldrich | I13: >99.9% (GC) | J13: SHBQ5769 | K13: 800 | L13: g | M13: 150.22 | N13: 233 | O13: - | P13: 0.96 | R13: - | S13: - | T13: - | U13: - | V13: - | W13: Active | AA13: carvone | AB13: 150.22 | AC13: 0.992
A14: carvone | B14: L-Carvone | C14: (-)-Carvone | D14: 6485-40-1 | E14: C10H14O | F14: C=C(C)[C@@H]1CC=C(C)C(=O)C1 | G14: 1.2 | H14: Sigma-Aldrich | I14: 99.2% (GC) | J14: SHBQ8402 | K14: 1 | L14: kg | M14: 150.22 | N14: 226 | O14: - | P14: 0.96 | R14: - | S14: - | T14: - | U14: - | V14: - | W14: Active | AA14: camphor | AB14: 152.24 | AC14: 0.969
A15: camphor | B15: DL-Camphor | C15: - | D15: 76-22-2 | E15: C10H16O | F15: CC1(C)C2CCC1(C)C(=O)C2 | G15: 3.2 | H15: Sigma-Aldrich | I15: 96.9% (GC) | J15: SDBB0718 | K15: 250 | L15: g | M15: 152.24 | N15: 210 | O15: - | P15: 0.99 | R15: - | S15: - | T15: - | U15: - | V15: - | W15: Active | AA15: geraniol | AB15: 154.25 | AC15: 0.989
A16: geraniol | B16: Geraniol | C16: - | D16: 106-24-1 | E16: C10H18O | F16: CC(C)=CCC/C(C)=C/CO | G16: 2.3 | H16: Sigma-Aldrich | I16: 98.9% (GC) | J16: SHBP7700 | K16: 700 | L16: g | M16: 154.25 | N16: 229 | O16: - | P16: 0.889 | R16: - | S16: - | T16: - | U16: - | V16: - | W16: Active | AA16: carvacrol | AB16: 150.22 | AC16: 0.997
A17: carvacrol | B17: Carvacrol | C17: - | D17: 499-75-2 | E17: C10H14O | F17: Cc1ccc(C(C)C)cc1O | G17: 2.1 | H17: Sigma-Aldrich | I17: 99.7% (GC) | J17: SHBQ9085 | K17: 400? | L17: mL | M17: 150.22 | N17: 239 | O17: - | P17: 0.977 | R17: - | S17: - | T17: - | U17: - | V17: - | W17: Active | AA17: eugenol | AB17: 164.2 | AC17: 0.992
A18: eugenol | B18: Eugenol | C18: - | D18: 97-53-0 | E18: C10H12O2 | F18: C=CCc1ccc(O)c(OC)c1 | G18: 1.3 | H18: Sigma-Aldrich | I18: 99.2% (GC) | J18: SHBM4053 | K18: 500? | L18: mL | M18: 164.2 | N18: 215 | O18: - | P18: 1.06 | R18: - | S18: - | T18: - | U18: - | V18: - | W18: Active
A19: h2o | B19: Water | C19: - | D19: - | E19: - | G19: - | H19: - | I19: HPLC | J19: - | K19: - | L19: - | M19: 18.02 | N19: 100 | O19: - | R19: - | S19: - | T19: - | U19: - | V19: - | W19: Active
B21: Aroma (soluto)
B22: Solventes
B23: DESs
B24: Agua (diluyente)

Sheet Lab_Solventes
A1: LAB SHEET — β-ionone (trans) + Solvent + Water
A2: Add in order: tube → water → aroma → solvent. Record cumulative balance reading after each addition.
A4: ρ_aroma (g/mL): | B4: =Componentes!P4 -> 0.94498 | C4: β-ionone
A5: ρ_water (g/mL): | B5: 0.997
B7: Pipetting guide (from predictions) | F7: Record on balance | J7: Auto-calculated by difference
A9: # | B9: Solvent | C9: TL# | D9: V_water est (mL) | E9: V_aroma est (mL) | F9: V_solv est (mL) | G9: W_tube (g) | H9: W +water (g) | I9: W +aroma (g) | J9: W +solv (g) | K9: m_water (g) | L9: m_aroma (g) | M9: m_solvent (g) | N9: m_total (g) | O9: w_water | P9: w_aroma | Q9: w_solvent | R9: Notes
A10: BH1 | B10: hexoh | C10: 1 | D10: =IF(predicciones_pcsaft!E18="","",predicciones_pcsaft!E18*7/$B$5) -> 3.5449348 | E10: =IF(predicciones_pcsaft!C18="","",predicciones_pcsaft!C18*7/$B$4) -> 3.518593 | F10: =IF(predicciones_pcsaft!D18="","",predicciones_pcsaft!D18*7/Componentes!P9) -> 0.17183054 | K10: =IF(OR(G10="",H10=""),"",H10-G10) | L10: =IF(OR(H10="",I10=""),"",I10-H10) | M10: =IF(OR(I10="",J10=""),"",J10-I10) | N10: =IF(OR(G10="",J10=""),"",J10-G10) | O10: =IF(N10="","",K10/N10) | P10: =IF(N10="","",L10/N10) | Q10: =IF(N10="","",M10/N10)
A11: BH2 | C11: 2 | D11: =IF(predicciones_pcsaft!E19="","",predicciones_pcsaft!E19*7/$B$5) -> 3.8601805 | E11: =IF(predicciones_pcsaft!C19="","",predicciones_pcsaft!C19*7/$B$4) -> 0.1496328 | F11: =IF(predicciones_pcsaft!D19="","",predicciones_pcsaft!D19*7/Componentes!P9) -> 3.6759767 | K11: =IF(OR(G11="",H11=""),"",H11-G11) | L11: =IF(OR(H11="",I11=""),"",I11-H11) | M11: =IF(OR(I11="",J11=""),"",J11-I11) | N11: =IF(OR(G11="",J11=""),"",J11-G11) | O11: =IF(N11="","",K11/N11) | P11: =IF(N11="","",L11/N11) | Q11: =IF(N11="","",M11/N11)
A12: BH3 | C12: 3 | D12: =IF(predicciones_pcsaft!E20="","",predicciones_pcsaft!E20*7/$B$5) -> 3.6790371 | E12: =IF(predicciones_pcsaft!C20="","",predicciones_pcsaft!C20*7/$B$4) -> 1.9600415 | F12: =IF(predicciones_pcsaft!D20="","",predicciones_pcsaft!D20*7/Componentes!P9) -> 1.8072127 | K12: =IF(OR(G12="",H12=""),"",H12-G12) | L12: =IF(OR(H12="",I12=""),"",I12-H12) | M12: =IF(OR(I12="",J12=""),"",J12-I12) | N12: =IF(OR(G12="",J12=""),"",J12-G12) | O12: =IF(N12="","",K12/N12) | P12: =IF(N12="","",L12/N12) | Q12: =IF(N12="","",M12/N12)
A13: BH4 | C13: 4 | D13: =IF(predicciones_pcsaft!E21="","",predicciones_pcsaft!E21*7/$B$5) -> 3.6074223 | E13: =IF(predicciones_pcsaft!C21="","",predicciones_pcsaft!C21*7/$B$4) -> 2.7659845 | F13: =IF(predicciones_pcsaft!D21="","",predicciones_pcsaft!D21*7/Componentes!P9) -> 0.96430272 | K13: =IF(OR(G13="",H13=""),"",H13-G13) | L13: =IF(OR(H13="",I13=""),"",I13-H13) | M13: =IF(OR(I13="",J13=""),"",J13-I13) | N13: =IF(OR(G13="",J13=""),"",J13-G13) | O13: =IF(N13="","",K13/N13) | P13: =IF(N13="","",L13/N13) | Q13: =IF(N13="","",M13/N13)
A14: BH5 | C14: 5 | D14: =IF(predicciones_pcsaft!E22="","",predicciones_pcsaft!E22*7/$B$5) -> 3.7611836 | E14: =IF(predicciones_pcsaft!C22="","",predicciones_pcsaft!C22*7/$B$4) -> 1.0992825 | F14: =IF(predicciones_pcsaft!D22="","",predicciones_pcsaft!D22*7/Componentes!P9) -> 2.7005606 | K14: =IF(OR(G14="",H14=""),"",H14-G14) | L14: =IF(OR(H14="",I14=""),"",I14-H14) | M14: =IF(OR(I14="",J14=""),"",J14-I14) | N14: =IF(OR(G14="",J14=""),"",J14-G14) | O14: =IF(N14="","",K14/N14) | P14: =IF(N14="","",L14/N14) | Q14: =IF(N14="","",M14/N14)
A16: BM1 | B16: mibk | C16: 1 | D16: =IF(predicciones_pcsaft!E30="","",predicciones_pcsaft!E30*7/$B$5) -> 3.8187563 | E16: =IF(predicciones_pcsaft!C30="","",predicciones_pcsaft!C30*7/$B$4) -> 0.15111431 | F16: =IF(predicciones_pcsaft!D30="","",predicciones_pcsaft!D30*7/Componentes!P11) -> 3.8055725 | K16: =IF(OR(G16="",H16=""),"",H16-G16) | L16: =IF(OR(H16="",I16=""),"",I16-H16) | M16: =IF(OR(I16="",J16=""),"",J16-I16) | N16: =IF(OR(G16="",J16=""),"",J16-G16) | O16: =IF(N16="","",K16/N16) | P16: =IF(N16="","",L16/N16) | Q16: =IF(N16="","",M16/N16)
A17: BM2 | C17: 2 | D17: =IF(predicciones_pcsaft!E31="","",predicciones_pcsaft!E31*7/$B$5) -> 3.546339 | E17: =IF(predicciones_pcsaft!C31="","",predicciones_pcsaft!C31*7/$B$4) -> 3.5171115 | F17: =IF(predicciones_pcsaft!D31="","",predicciones_pcsaft!D31*7/Componentes!P11) -> 0.17556118 | K17: =IF(OR(G17="",H17=""),"",H17-G17) | L17: =IF(OR(H17="",I17=""),"",I17-H17) | M17: =IF(OR(I17="",J17=""),"",J17-I17) | N17: =IF(OR(G17="",J17=""),"",J17-G17) | O17: =IF(N17="","",K17/N17) | P17: =IF(N17="","",L17/N17) | Q17: =IF(N17="","",M17/N17)
A18: BM3 | C18: 3 | D18: =IF(predicciones_pcsaft!E32="","",predicciones_pcsaft!E32*7/$B$5) -> 3.678335 | E18: =IF(predicciones_pcsaft!C32="","",predicciones_pcsaft!C32*7/$B$4) -> 1.9296705 | F18: =IF(predicciones_pcsaft!D32="","",predicciones_pcsaft!D32*7/Componentes!P11) -> 1.8822605 | K18: =IF(OR(G18="",H18=""),"",H18-G18) | L18: =IF(OR(H18="",I18=""),"",I18-H18) | M18: =IF(OR(I18="",J18=""),"",J18-I18) | N18: =IF(OR(G18="",J18=""),"",J18-G18) | O18: =IF(N18="","",K18/N18) | P18: =IF(N18="","",L18/N18) | Q18: =IF(N18="","",M18/N18)
A19: BM4 | C19: 4 | D19: =IF(predicciones_pcsaft!E33="","",predicciones_pcsaft!E33*7/$B$5) -> 3.7471414 | E19: =IF(predicciones_pcsaft!C33="","",predicciones_pcsaft!C33*7/$B$4) -> 1.0689115 | F19: =IF(predicciones_pcsaft!D33="","",predicciones_pcsaft!D33*7/Componentes!P11) -> 2.8124727 | K19: =IF(OR(G19="",H19=""),"",H19-G19) | L19: =IF(OR(H19="",I19=""),"",I19-H19) | M19: =IF(OR(I19="",J19=""),"",J19-I19) | N19: =IF(OR(G19="",J19=""),"",J19-G19) | O19: =IF(N19="","",K19/N19) | P19: =IF(N19="","",L19/N19) | Q19: =IF(N19="","",M19/N19)
A20: BM5 | C20: 5 | D20: =IF(predicciones_pcsaft!E34="","",predicciones_pcsaft!E34*7/$B$5) -> 3.6116349 | E20: =IF(predicciones_pcsaft!C34="","",predicciones_pcsaft!C34*7/$B$4) -> 2.7489471 | F20: =IF(predicciones_pcsaft!D34="","",predicciones_pcsaft!D34*7/Componentes!P11) -> 1.0000873 | K20: =IF(OR(G20="",H20=""),"",H20-G20) | L20: =IF(OR(H20="",I20=""),"",I20-H20) | M20: =IF(OR(I20="",J20=""),"",J20-I20) | N20: =IF(OR(G20="",J20=""),"",J20-G20) | O20: =IF(N20="","",K20/N20) | P20: =IF(N20="","",L20/N20) | Q20: =IF(N20="","",M20/N20)
A22: BO1 | B22: 2octanone | C22: 1 | D22: =IF(predicciones_pcsaft!E36="","",predicciones_pcsaft!E36*7/$B$5) -> 3.7801404 | E22: =IF(predicciones_pcsaft!C36="","",predicciones_pcsaft!C36*7/$B$4) -> 0.14889204 | F22: =IF(predicciones_pcsaft!D36="","",predicciones_pcsaft!D36*7/Componentes!P12) -> 3.7732278 | K22: =IF(OR(G22="",H22=""),"",H22-G22) | L22: =IF(OR(H22="",I22=""),"",I22-H22) | M22: =IF(OR(I22="",J22=""),"",J22-I22) | N22: =IF(OR(G22="",J22=""),"",J22-G22) | O22: =IF(N22="","",K22/N22) | P22: =IF(N22="","",L22/N22) | Q22: =IF(N22="","",M22/N22)
A23: BO2 | C23: 2 | D23: =IF(predicciones_pcsaft!E37="","",predicciones_pcsaft!E37*7/$B$5) -> 3.5442327 | E23: =IF(predicciones_pcsaft!C37="","",predicciones_pcsaft!C37*7/$B$4) -> 3.5171115 | F23: =IF(predicciones_pcsaft!D37="","",predicciones_pcsaft!D37*7/Componentes!P12) -> 0.1743462 | K23: =IF(OR(G23="",H23=""),"",H23-G23) | L23: =IF(OR(H23="",I23=""),"",I23-H23) | M23: =IF(OR(I23="",J23=""),"",J23-I23) | N23: =IF(OR(G23="",J23=""),"",J23-G23) | O23: =IF(N23="","",K23/N23) | P23: =IF(N23="","",L23/N23) | Q23: =IF(N23="","",M23/N23)
A24: BO3 | C24: 3 | D24: =IF(predicciones_pcsaft!E38="","",predicciones_pcsaft!E38*7/$B$5) -> 3.6579739 | E24: =IF(predicciones_pcsaft!C38="","",predicciones_pcsaft!C38*7/$B$4) -> 1.9044848 | F24: =IF(predicciones_pcsaft!D38="","",predicciones_pcsaft!D38*7/Componentes!P12) -> 1.8955876 | K24: =IF(OR(G24="",H24=""),"",H24-G24) | L24: =IF(OR(H24="",I24=""),"",I24-H24) | M24: =IF(OR(I24="",J24=""),"",J24-I24) | N24: =IF(OR(G24="",J24=""),"",J24-G24) | O24: =IF(N24="","",K24/N24) | P24: =IF(N24="","",L24/N24) | Q24: =IF(N24="","",M24/N24)
A25: BO4 | C25: 4 | D25: =IF(predicciones_pcsaft!E39="","",predicciones_pcsaft!E39*7/$B$5) -> 3.6004012 | E25: =IF(predicciones_pcsaft!C39="","",predicciones_pcsaft!C39*7/$B$4) -> 2.7274651 | F25: =IF(predicciones_pcsaft!D39="","",predicciones_pcsaft!D39*7/Componentes!P12) -> 1.0170195 | K25: =IF(OR(G25="",H25=""),"",H25-G25) | L25: =IF(OR(H25="",I25=""),"",I25-H25) | M25: =IF(OR(I25="",J25=""),"",J25-I25) | N25: =IF(OR(G25="",J25=""),"",J25-G25) | O25: =IF(N25="","",K25/N25) | P25: =IF(N25="","",L25/N25) | Q25: =IF(N25="","",M25/N25)
A26: BO5 | C26: 5 | D26: =IF(predicciones_pcsaft!E40="","",predicciones_pcsaft!E40*7/$B$5) -> 3.7183551 | E26: =IF(predicciones_pcsaft!C40="","",predicciones_pcsaft!C40*7/$B$4) -> 1.0452073 | F26: =IF(predicciones_pcsaft!D40="","",predicciones_pcsaft!D40*7/Componentes!P12) -> 2.8143237 | K26: =IF(OR(G26="",H26=""),"",H26-G26) | L26: =IF(OR(H26="",I26=""),"",I26-H26) | M26: =IF(OR(I26="",J26=""),"",J26-I26) | N26: =IF(OR(G26="",J26=""),"",J26-G26) | O26: =IF(N26="","",K26/N26) | P26: =IF(N26="","",L26/N26) | Q26: =IF(N26="","",M26/N26)

Sheet Sampling
A1: H — 1-hexanol | H1: V_sample: | I1: 200 | J1: µL | K1: +800 µL IPA
A2: β-ionone + 1-hexanol + Water | Dilution: 200 µL sample + 800 µL IPA | I2: ■ KF routine | J2: □ KF if fishy
A3: System | B3: Phase | C3: Rep | D3: GC Vial ID | E3: W_vial (g) | F3: W +sample (g) | G3: W +solvent (g) | H3: m_sample (g) | I3: m_solvent (g) | J3: DF | K3: KF w_water (%) | L3: Notes
A4: BH1 | B4: Top | C4: 1 | D4: H1-T1 | H4: =IF(OR(E4="",F4=""),"",F4-E4) | I4: =IF(OR(F4="",G4=""),"",G4-F4) | J4: =IF(OR(H4="",I4=""),"",(H4+I4)/H4)
C5: 2 | D5: H1-T2 | H5: =IF(OR(E5="",F5=""),"",F5-E5) | I5: =IF(OR(F5="",G5=""),"",G5-F5) | J5: =IF(OR(H5="",I5=""),"",(H5+I5)/H5)
B6: Bot | C6: 1 | D6: H1-B1 | H6: =IF(OR(E6="",F6=""),"",F6-E6) | I6: =IF(OR(F6="",G6=""),"",G6-F6) | J6: =IF(OR(H6="",I6=""),"",(H6+I6)/H6)
C7: 2 | D7: H1-B2 | H7: =IF(OR(E7="",F7=""),"",F7-E7) | I7: =IF(OR(F7="",G7=""),"",G7-F7) | J7: =IF(OR(H7="",I7=""),"",(H7+I7)/H7)
A8: BH2 | B8: Top | C8: 1 | D8: H2-T1 | H8: =IF(OR(E8="",F8=""),"",F8-E8) | I8: =IF(OR(F8="",G8=""),"",G8-F8) | J8: =IF(OR(H8="",I8=""),"",(H8+I8)/H8)
C9: 2 | D9: H2-T2 | H9: =IF(OR(E9="",F9=""),"",F9-E9) | I9: =IF(OR(F9="",G9=""),"",G9-F9) | J9: =IF(OR(H9="",I9=""),"",(H9+I9)/H9)
B10: Bot | C10: 1 | D10: H2-B1 | H10: =IF(OR(E10="",F10=""),"",F10-E10) | I10: =IF(OR(F10="",G10=""),"",G10-F10) | J10: =IF(OR(H10="",I10=""),"",(H10+I10)/H10)
C11: 2 | D11: H2-B2 | H11: =IF(OR(E11="",F11=""),"",F11-E11) | I11: =IF(OR(F11="",G11=""),"",G11-F11) | J11: =IF(OR(H11="",I11=""),"",(H11+I11)/H11)
A12: BH3 | B12: Top | C12: 1 | D12: H3-T1 | H12: =IF(OR(E12="",F12=""),"",F12-E12) | I12: =IF(OR(F12="",G12=""),"",G12-F12) | J12: =IF(OR(H12="",I12=""),"",(H12+I12)/H12)
C13: 2 | D13: H3-T2 | H13: =IF(OR(E13="",F13=""),"",F13-E13) | I13: =IF(OR(F13="",G13=""),"",G13-F13) | J13: =IF(OR(H13="",I13=""),"",(H13+I13)/H13)
B14: Bot | C14: 1 | D14: H3-B1 | H14: =IF(OR(E14="",F14=""),"",F14-E14) | I14: =IF(OR(F14="",G14=""),"",G14-F14) | J14: =IF(OR(H14="",I14=""),"",(H14+I14)/H14)
C15: 2 | D15: H3-B2 | H15: =IF(OR(E15="",F15=""),"",F15-E15) | I15: =IF(OR(F15="",G15=""),"",G15-F15) | J15: =IF(OR(H15="",I15=""),"",(H15+I15)/H15)
A16: BH4 | B16: Top | C16: 1 | D16: H4-T1 | H16: =IF(OR(E16="",F16=""),"",F16-E16) | I16: =IF(OR(F16="",G16=""),"",G16-F16) | J16: =IF(OR(H16="",I16=""),"",(H16+I16)/H16)
C17: 2 | D17: H4-T2 | H17: =IF(OR(E17="",F17=""),"",F17-E17) | I17: =IF(OR(F17="",G17=""),"",G17-F17) | J17: =IF(OR(H17="",I17=""),"",(H17+I17)/H17)
B18: Bot | C18: 1 | D18: H4-B1 | H18: =IF(OR(E18="",F18=""),"",F18-E18) | I18: =IF(OR(F18="",G18=""),"",G18-F18) | J18: =IF(OR(H18="",I18=""),"",(H18+I18)/H18)
C19: 2 | D19: H4-B2 | H19: =IF(OR(E19="",F19=""),"",F19-E19) | I19: =IF(OR(F19="",G19=""),"",G19-F19) | J19: =IF(OR(H19="",I19=""),"",(H19+I19)/H19)
A20: BH5 | B20: Top | C20: 1 | D20: H5-T1 | H20: =IF(OR(E20="",F20=""),"",F20-E20) | I20: =IF(OR(F20="",G20=""),"",G20-F20) | J20: =IF(OR(H20="",I20=""),"",(H20+I20)/H20)
C21: 2 | D21: H5-T2 | H21: =IF(OR(E21="",F21=""),"",F21-E21) | I21: =IF(OR(F21="",G21=""),"",G21-F21) | J21: =IF(OR(H21="",I21=""),"",(H21+I21)/H21)
B22: Bot | C22: 1 | D22: H5-B1 | H22: =IF(OR(E22="",F22=""),"",F22-E22) | I22: =IF(OR(F22="",G22=""),"",G22-F22) | J22: =IF(OR(H22="",I22=""),"",(H22+I22)/H22)
C23: 2 | D23: H5-B2 | H23: =IF(OR(E23="",F23=""),"",F23-E23) | I23: =IF(OR(F23="",G23=""),"",G23-F23) | J23: =IF(OR(H23="",I23=""),"",(H23+I23)/H23)
A24: M — MIBK | H24: V_sample: | I24: 200 | J24: µL | K24: +800 µL IPA
A25: β-ionone + MIBK + Water | Dilution: 200 µL sample + 800 µL IPA | I25: ■ KF routine | J25: □ KF if fishy
A26: System | B26: Phase | C26: Rep | D26: GC Vial ID | E26: W_vial (g) | F26: W +sample (g) | G26: W +solvent (g) | H26: m_sample (g) | I26: m_solvent (g) | J26: DF | K26: KF w_water (%) | L26: Notes
A27: BM1 | B27: Top | C27: 1 | D27: M1-T1 | H27: =IF(OR(E27="",F27=""),"",F27-E27) | I27: =IF(OR(F27="",G27=""),"",G27-F27) | J27: =IF(OR(H27="",I27=""),"",(H27+I27)/H27)
C28: 2 | D28: M1-T2 | H28: =IF(OR(E28="",F28=""),"",F28-E28) | I28: =IF(OR(F28="",G28=""),"",G28-F28) | J28: =IF(OR(H28="",I28=""),"",(H28+I28)/H28)
B29: Bot | C29: 1 | D29: M1-B1 | H29: =IF(OR(E29="",F29=""),"",F29-E29) | I29: =IF(OR(F29="",G29=""),"",G29-F29) | J29: =IF(OR(H29="",I29=""),"",(H29+I29)/H29)
C30: 2 | D30: M1-B2 | H30: =IF(OR(E30="",F30=""),"",F30-E30) | I30: =IF(OR(F30="",G30=""),"",G30-F30) | J30: =IF(OR(H30="",I30=""),"",(H30+I30)/H30)
A31: BM2 | B31: Top | C31: 1 | D31: M2-T1 | H31: =IF(OR(E31="",F31=""),"",F31-E31) | I31: =IF(OR(F31="",G31=""),"",G31-F31) | J31: =IF(OR(H31="",I31=""),"",(H31+I31)/H31)
C32: 2 | D32: M2-T2 | H32: =IF(OR(E32="",F32=""),"",F32-E32) | I32: =IF(OR(F32="",G32=""),"",G32-F32) | J32: =IF(OR(H32="",I32=""),"",(H32+I32)/H32)
B33: Bot | C33: 1 | D33: M2-B1 | H33: =IF(OR(E33="",F33=""),"",F33-E33) | I33: =IF(OR(F33="",G33=""),"",G33-F33) | J33: =IF(OR(H33="",I33=""),"",(H33+I33)/H33)
C34: 2 | D34: M2-B2 | H34: =IF(OR(E34="",F34=""),"",F34-E34) | I34: =IF(OR(F34="",G34=""),"",G34-F34) | J34: =IF(OR(H34="",I34=""),"",(H34+I34)/H34)
A35: BM3 | B35: Top | C35: 1 | D35: M3-T1 | H35: =IF(OR(E35="",F35=""),"",F35-E35) | I35: =IF(OR(F35="",G35=""),"",G35-F35) | J35: =IF(OR(H35="",I35=""),"",(H35+I35)/H35)
C36: 2 | D36: M3-T2 | H36: =IF(OR(E36="",F36=""),"",F36-E36) | I36: =IF(OR(F36="",G36=""),"",G36-F36) | J36: =IF(OR(H36="",I36=""),"",(H36+I36)/H36)
B37: Bot | C37: 1 | D37: M3-B1 | H37: =IF(OR(E37="",F37=""),"",F37-E37) | I37: =IF(OR(F37="",G37=""),"",G37-F37) | J37: =IF(OR(H37="",I37=""),"",(H37+I37)/H37)
C38: 2 | D38: M3-B2 | H38: =IF(OR(E38="",F38=""),"",F38-E38) | I38: =IF(OR(F38="",G38=""),"",G38-F38) | J38: =IF(OR(H38="",I38=""),"",(H38+I38)/H38)
A39: BM4 | B39: Top | C39: 1 | D39: M4-T1 | H39: =IF(OR(E39="",F39=""),"",F39-E39) | I39: =IF(OR(F39="",G39=""),"",G39-F39) | J39: =IF(OR(H39="",I39=""),"",(H39+I39)/H39)
C40: 2 | D40: M4-T2 | H40: =IF(OR(E40="",F40=""),"",F40-E40) | I40: =IF(OR(F40="",G40=""),"",G40-F40) | J40: =IF(OR(H40="",I40=""),"",(H40+I40)/H40)
...
